Workbook

Sheet CARÁTULA
C2: REGISTRO PEDAGÓGICO
C4: DATOS REFERENCIALES | H4: FECHAS DE INICIO Y FINAL
B6: DISTRITO EDUCATIVO | C6: EL ALTO | H6: PERIODO ACADÉMICO ANUAL
B8: NÚCLEO EDUCATIVO | C8: EL ALTO-1
H9: PRIMER TRIMESTRE
B10: UNIDAD EDUCATIVA | C10: INTERANDINO BOLIVIANO | H10: INICIO | J10: FINAL
H11: 46055 | J11: 46150
B12: DIRECTOR/A | C12: PROF. ADELA GUERRA CASTAÑOS
H13: SEGUNDO TRIMESTRE
B14: MAESTRO/A | C14: MARCO A. CHAVEZ CHOQUEHUANCA
H15: INICIO | J15: FINAL
B16: NIVEL | C16: SECUNDARIO | H16: 46153 | J16: 46326
B18: AÑO DE ESCOLARIDAD | C18: 5° "A" DE SECUNDARIA | H18: TERCER TRIMESTRE
B20: ÁREA | C20: CIENCIAS SOCIALES | H20: INICIO | J20: FINAL
H21: 46266 | J21: 46358
B22: GESTIÓN | C22: 2026

Sheet FILIACIÓN
B2: REGISTRO DE FILIACIÓN
B4: UNIDAD EDUCATIVA: | C4: =CARÁTULA!$C$10 -> INTERANDINO BOLIVIANO | E4: ÁREA | F4: =CARÁTULA!$C$20 -> CIENCIAS SOCIALES
B5: NIVEL: | C5: =CARÁTULA!$C$16 -> SECUNDARIO | E5: DOCENTE | F5: =CARÁTULA!$C$14 -> MARCO A. CHAVEZ CHOQUEHUANCA
B6: GRADO: | C6: =CARÁTULA!$C$18 -> 5° "A" DE SECUNDARIA | E6: FECHA | F6: =TODAY() -> 46138
A8: Nº | B8: APELLIDOS Y NOMBRES | C8: CIUDAD | D8: EDAD | E8: C.I. | F8: BARRIO/CALLE | G8: PADRE/MADRE | H8: TELF./ CELULAR
A9: 1 | B9: APALA YUJRA ROSELIN ANDREA
A10: 2 | B10: APAZA ANGULO ARELY BIANCA
A11: 3 | B11: APAZA TICONA DANAE ALEXANDRA
A12: 4 | B12: ARDORES USNAYO CAMERON GAELLE
A13: 5 | B13: BAUTISTA BLANCO GREIS EVANI
A14: 6 | B14: CACERES FLORES KIMBERLY AVRIL
A15: 7 | B15: CALLE MARQUEZ SOL MADELEY
A16: 8 | B16: CALLISAYA CORONEL BELLA LUZ JAEL
A17: 9 | B17: CALLISAYA CRUZ CAMILA RIZEL
A18: 10 | B18: CHARCAS COLQUE ALEJANDRA BRIDGET
A19: 11 | B19: CONDORI CHOQUE SAYUMI
A20: 12 | B20: CONDORI MARQUEZ JHUREM ALEX
... A42: 34 | B42: VENTURA SALCEDO GABRIEL
A43: 35
A44: 36
A45: 37
A46: 38
A47: 39
A48: 40

Sheet ASIS 1 TRIM
A1: CONTROL DE ASISTENCIA 1º TRIMESTRE
B3: UNIDAD EDUCATIVA | C3: =CARÁTULA!$C$10 -> INTERANDINO BOLIVIANO
B4: NIVEL | C4: =CARÁTULA!$C$16 -> SECUNDARIO | R4: INICIO TRIMESTRE | AB4: =CARÁTULA!H11 -> 46055 | AI4: TRIMESTRE
B5: GRADO | C5: =CARÁTULA!$C$18 -> 5° "A" DE SECUNDARIA | R5: FIN TRIMESTRE | AB5: =CARÁTULA!J11 -> 46150 | AI5: 1er.
B6: DOCENTE | C6: =CARÁTULA!$C$14 -> MARCO A. CHAVEZ CHOQUEHUANCA | R6: FECHA ACTUAL | AB6: =TODAY() -> 46138
A7: Nº | B7: NÓMINA DE ESTUDIANTES Apellidos y Nombres | C7: 46056 | D7: 46059 | E7: 46063 | F7: 46066 | G7: 46070 | H7: 46073 | I7: 46077 | J7: 46108 | K7: 46084 | L7: 46087 | M7: 46091 | N7: 46094 | O7: 46098 | P7: 46101 | Q7: 46105 | R7: 46108 | S7: 46112 | T7: 46115 | U7: 46119 | V7: 46122 | W7: 46129 | X7: 17/4/2026 R. | Y7: 46133 | Z7: 46136 | AI7: Asist. (A) | AJ7: Faltas (F) | AK7: Retrasos (R) | AL7: Licencias (L) | AM7: DÍAS TRABAJADOS
A8: 1 | B8: =FILIACIÓN!$B9 -> APALA YUJRA ROSELIN ANDREA | C8: A | D8: A | E8: A | F8: A | H8: A | I8: A | J8: A | K8: A | L8: A | M8: A | N8: A | O8: A | P8: A | Q8: A | R8: A | S8: A | U8: A | V8: A | W8: A | X8: A | Y8: A | Z8: A | AI8: =IF(COUNTIF(C8:AH8,"A")=0,"",COUNTIF(C8:AH8,"A")) -> 22 | AJ8: =IF(COUNTIF(C8:AH8,"F")=0,"",COUNTIF(C8:AH8,"F")) | AK8: =IF(COUNTIF(C8:AH8,"R")=0,"",COUNTIF(C8:AH8,"R")) | AL8: =IF(COUNTIF(C8:AH8,"L")=0,"",COUNTIF(C8:AH8,"L")) | AM8: =SUM(AI8:AL8) -> 22
A9: 2 | B9: =FILIACIÓN!$B10 -> APAZA ANGULO ARELY BIANCA | C9: A | D9: A | E9: A | F9: A | H9: A | I9: A | J9: A | K9: A | L9: F | M9: F | N9: A | O9: A | P9: A | Q9: A | R9: A | S9: A | U9: A | V9: A | W9: A | X9: A | Y9: A | Z9: A | AI9: =IF(COUNTIF(C9:AH9,"A")=0,"",COUNTIF(C9:AH9,"A")) -> 20 | AJ9: =IF(COUNTIF(C9:AH9,"F")=0,"",COUNTIF(C9:AH9,"F")) -> 2 | AK9: =IF(COUNTIF(C9:AH9,"R")=0,"",COUNTIF(C9:AH9,"R")) | AL9: =IF(COUNTIF(C9:AH9,"L")=0,"",COUNTIF(C9:AH9,"L")) | AM9: =SUM(AI9:AL9) -> 22
A10: 3 | B10: =FILIACIÓN!$B11 -> APAZA TICONA DANAE ALEXANDRA | C10: A | D10: A | E10: A | F10: A | H10: A | I10: A | J10: A | K10: A | L10: A | M10: A | N10: A | O10: A | P10: A | Q10: A | R10: A | S10: A | U10: A | V10: A | W10: A | X10: A | Y10: A | Z10: A | AI10: =IF(COUNTIF(C10:AH10,"A")=0,"",COUNTIF(C10:AH10,"A")) -> 22 | AJ10: =IF(COUNTIF(C10:AH10,"F")=0,"",COUNTIF(C10:AH10,"F")) | AK10: =IF(COUNTIF(C10:AH10,"R")=0,"",COUNTIF(C10:AH10,"R")) | AL10: =IF(COUNTIF(C10:AH10,"L")=0,"",COUNTIF(C10:AH10,"L")) | AM10: =SUM(AI10:AL10) -> 22
A11: 4 | B11: =FILIACIÓN!$B12 -> ARDORES USNAYO CAMERON GAELLE | C11: A | D11: A | E11: A | F11: A | H11: A | I11: A | J11: A | K11: A | L11: A | M11: A | N11: A | O11: A | P11: A | Q11: A | R11: A | S11: A | U11: A | V11: A | W11: A | X11: A | Y11: A | Z11: A | AI11: =IF(COUNTIF(C11:AH11,"A")=0,"",COUNTIF(C11:AH11,"A")) -> 22 | AJ11: =IF(COUNTIF(C11:AH11,"F")=0,"",COUNTIF(C11:AH11,"F")) | AK11: =IF(COUNTIF(C11:AH11,"R")=0,"",COUNTIF(C11:AH11,"R")) | AL11: =IF(COUNTIF(C11:AH11,"L")=0,"",COUNTIF(C11:AH11,"L")) | AM11: =SUM(AI11:AL11) -> 22
A12: 5 | B12: =FILIACIÓN!$B13 -> BAUTISTA BLANCO GREIS EVANI | C12: A | D12: A | E12: A | F12: A | H12: A | I12: A | J12: A | K12: A | L12: A | M12: A | N12: A | O12: A | P12: A | Q12: A | R12: A | S12: F | U12: F | V12: A | W12: A | X12: F | Y12: A | Z12: A | AI12: =IF(COUNTIF(C12:AH12,"A")=0,"",COUNTIF(C12:AH12,"A")) -> 19 | AJ12: =IF(COUNTIF(C12:AH12,"F")=0,"",COUNTIF(C12:AH12,"F")) -> 3 | AK12: =IF(COUNTIF(C12:AH12,"R")=0,"",COUNTIF(C12:AH12,"R")) | AL12: =IF(COUNTIF(C12:AH12,"L")=0,"",COUNTIF(C12:AH12,"L")) | AM12: =SUM(AI12:AL12) -> 22
A13: 6 | B13: =FILIACIÓN!$B14 -> CACERES FLORES KIMBERLY AVRIL | C13: A | D13: A | E13: A | F13: A | H13: A | I13: A | J13: A | K13: A | L13: A | M13: A | N13: A | O13: A | P13: A | Q13: A | R13: A | S13: A | U13: A | V13: A | W13: A | X13: A | Y13: A | Z13: A | AI13: =IF(COUNTIF(C13:AH13,"A")=0,"",COUNTIF(C13:AH13,"A")) -> 22 | AJ13: =IF(COUNTIF(C13:AH13,"F")=0,"",COUNTIF(C13:AH13,"F")) | AK13: =IF(COUNTIF(C13:AH13,"R")=0,"",COUNTIF(C13:AH13,"R")) | AL13: =IF(COUNTIF(C13:AH13,"L")=0,"",COUNTIF(C13:AH13,"L")) | AM13: =SUM(AI13:AL13) -> 22
A14: 7 | B14: =FILIACIÓN!$B15 -> CALLE MARQUEZ SOL MADELEY | C14: A | D14: A | E14: A | F14: A | H14: A | I14: A | J14: A | K14: A | L14: A | M14: A | N14: A | O14: A | P14: A | Q14: A | R14: A | S14: A | U14: A | V14: A | W14: A | X14: A | Y14: A | Z14: A | AI14: =IF(COUNTIF(C14:AH14,"A")=0,"",COUNTIF(C14:AH14,"A")) -> 22 | AJ14: =IF(COUNTIF(C14:AH14,"F")=0,"",COUNTIF(C14:AH14,"F")) | AK14: =IF(COUNTIF(C14:AH14,"R")=0,"",COUNTIF(C14:AH14,"R")) | AL14: =IF(COUNTIF(C14:AH14,"L")=0,"",COUNTIF(C14:AH14,"L")) | AM14: =SUM(AI14:AL14) -> 22
A15: 8 | B15: =FILIACIÓN!$B16 -> CALLISAYA CORONEL BELLA LUZ JAEL | C15: A | D15: A | E15: A | F15: A | H15: A | I15: A | J15: A | K15: A | L15: A | M15: A | N15: A | O15: A | P15: A | Q15: A | R15: A | S15: A | U15: A | V15: A | W15: A | X15: A | Y15: A | Z15: A | AI15: =IF(COUNTIF(C15:AH15,"A")=0,"",COUNTIF(C15:AH15,"A")) -> 22 | AJ15: =IF(COUNTIF(C15:AH15,"F")=0,"",COUNTIF(C15:AH15,"F")) | AK15: =IF(COUNTIF(C15:AH15,"R")=0,"",COUNTIF(C15:AH15,"R")) | AL15: =IF(COUNTIF(C15:AH15,"L")=0,"",COUNTIF(C15:AH15,"L")) | AM15: =SUM(AI15:AL15) -> 22
A16: 9 | B16: =FILIACIÓN!$B17 -> CALLISAYA CRUZ CAMILA RIZEL | C16: A | D16: A | E16: A | F16: A | H16: A | I16: A | J16: A | K16: L | L16: F | M16: A | N16: A | O16: A | P16: A | Q16: A | R16: A | S16: A | U16: A | V16: A | W16: A | X16: A | Y16: A | Z16: A | AI16: =IF(COUNTIF(C16:AH16,"A")=0,"",COUNTIF(C16:AH16,"A")) -> 20 | AJ16: =IF(COUNTIF(C16:AH16,"F")=0,"",COUNTIF(C16:AH16,"F")) -> 1 | AK16: =IF(COUNTIF(C16:AH16,"R")=0,"",COUNTIF(C16:AH16,"R")) | AL16: =IF(COUNTIF(C16:AH16,"L")=0,"",COUNTIF(C16:AH16,"L")) -> 1 | AM16: =SUM(AI16:AL16) -> 22
A17: 10 | B17: =FILIACIÓN!$B18 -> CHARCAS COLQUE ALEJANDRA BRIDGET | C17: A | D17: A | E17: F | F17: A | H17: A | I17: F | J17: A | K17: A | L17: F | M17: F | N17: A | O17: A | P17: A | Q17: A | R17: A | S17: A | U17: A | V17: A | W17: A | X17: A | Y17: F | Z17: A | AI17: =IF(COUNTIF(C17:AH17,"A")=0,"",COUNTIF(C17:AH17,"A")) -> 17 | AJ17: =IF(COUNTIF(C17:AH17,"F")=0,"",COUNTIF(C17:AH17,"F")) -> 5 | AK17: =IF(COUNTIF(C17:AH17,"R")=0,"",COUNTIF(C17:AH17,"R")) | AL17: =IF(COUNTIF(C17:AH17,"L")=0,"",COUNTIF(C17:AH17,"L")) | AM17: =SUM(AI17:AL17) -> 22
A18: 11 | B18: =FILIACIÓN!$B19 -> CONDORI CHOQUE SAYUMI | C18: A | D18: A | E18: A | F18: A | H18: A | I18: A | J18: A | K18: A | L18: A | M18: A | N18: A | O18: A | P18: A | Q18: A | R18: A | S18: A | U18: A | V18: A | W18: A | X18: A | Y18: A | Z18: A | AI18: =IF(COUNTIF(C18:AH18,"A")=0,"",COUNTIF(C18:AH18,"A")) -> 22 | AJ18: =IF(COUNTIF(C18:AH18,"F")=0,"",COUNTIF(C18:AH18,"F")) | AK18: =IF(COUNTIF(C18:AH18,"R")=0,"",COUNTIF(C18:AH18,"R")) | AL18: =IF(COUNTIF(C18:AH18,"L")=0,"",COUNTIF(C18:AH18,"L")) | AM18: =SUM(AI18:AL18) -> 22
A19: 12 | B19: =FILIACIÓN!$B20 -> CONDORI MARQUEZ JHUREM ALEX | C19: A | D19: A | E19: A | F19: A | H19: A | I19: A | J19: A | K19: A | L19: A | M19: F | N19: A | O19: A | P19: A | Q19: A | R19: A | S19: A | U19: A | V19: A | W19: A | X19: A | Y19: A | Z19: A | AI19: =IF(COUNTIF(C19:AH19,"A")=0,"",COUNTIF(C19:AH19,"A")) -> 21 | AJ19: =IF(COUNTIF(C19:AH19,"F")=0,"",COUNTIF(C19:AH19,"F")) -> 1 | AK19: =IF(COUNTIF(C19:AH19,"R")=0,"",COUNTIF(C19:AH19,"R")) | AL19: =IF(COUNTIF(C19:AH19,"L")=0,"",COUNTIF(C19:AH19,"L")) | AM19: =SUM(AI19:AL19) -> 22
... A41: 34 | B41: =FILIACIÓN!$B42 -> VENTURA SALCEDO GABRIEL | C41: A | D41: A | E41: A | F41: A | H41: A | I41: A | J41: A | K41: A | L41: A | M41: A | N41: A | O41: A | P41: A | Q41: A | R41: A | S41: A | U41: A | V41: A | W41: A | X41: A | Y41: A | Z41: A | AI41: =IF(COUNTIF(C41:AH41,"A")=0,"",COUNTIF(C41:AH41,"A")) -> 22 | AJ41: =IF(COUNTIF(C41:AH41,"F")=0,"",COUNTIF(C41:AH41,"F")) | AK41: =IF(COUNTIF(C41:AH41,"R")=0,"",COUNTIF(C41:AH41,"R")) | AL41: =IF(COUNTIF(C41:AH41,"L")=0,"",COUNTIF(C41:AH41,"L")) | AM41: =SUM(AI41:AL41) -> 22
A42: 35 | B42: =FILIACIÓN!$B43 -> 0 | AI42: =IF(COUNTIF(C42:AH42,"A")=0,"",COUNTIF(C42:AH42,"A")) | AJ42: =IF(COUNTIF(C42:AH42,"F")=0,"",COUNTIF(C42:AH42,"F")) | AK42: =IF(COUNTIF(C42:AH42,"R")=0,"",COUNTIF(C42:AH42,"R")) | AL42: =IF(COUNTIF(C42:AH42,"L")=0,"",COUNTIF(C42:AH42,"L")) | AM42: =SUM(AI42:AL42) -> 0
A43: 36 | B43: =FILIACIÓN!$B44 -> 0 | AI43: =IF(COUNTIF(C43:AH43,"A")=0,"",COUNTIF(C43:AH43,"A")) | AJ43: =IF(COUNTIF(C43:AH43,"F")=0,"",COUNTIF(C43:AH43,"F")) | AK43: =IF(COUNTIF(C43:AH43,"R")=0,"",COUNTIF(C43:AH43,"R")) | AL43: =IF(COUNTIF(C43:AH43,"L")=0,"",COUNTIF(C43:AH43,"L")) | AM43: =SUM(AI43:AL43) -> 0

Sheet ASIS 2 TRIM
A1: CONTROL DE ASISTENCIA 2º TRIMESTRE
B3: UNIDAD EDUCATIVA | C3: =CARÁTULA!$C$10 -> INTERANDINO BOLIVIANO
B4: NIVEL | C4: =CARÁTULA!$C$16 -> SECUNDARIO | R4: INICIO TRIMESTRE | AB4: =CARÁTULA!H16 -> 46153 | AI4: TRIMESTRE
B5: GRADO | C5: =CARÁTULA!$C$18 -> 5° "A" DE SECUNDARIA | R5: FIN TRIMESTRE | AB5: =CARÁTULA!J16 -> 46326 | AI5: 2do.
B6: DOCENTE | C6: =CARÁTULA!$C$14 -> MARCO A. CHAVEZ CHOQUEHUANCA | R6: FECHA ACTUAL | AB6: =TODAY() -> 46138
A7: Nº | B7: NÓMINA DE ESTUDIANTES Apellidos y Nombres | C7: 45694 | D7: 45701 | E7: 45708 | F7: 45715 | G7: 45722 | H7: 45729 | I7: 45736 | J7: 45743 | K7: 45750 | L7: 45757 | M7: 45764 | N7: 45771 | O7: 45778 | P7: 45785 | AI7: Asist. (A) | AJ7: Faltas (F) | AK7: Retrasos (R) | AL7: Licencias (L) | AM7: DÍAS TRABAJADOS
A8: 1 | B8: =FILIACIÓN!$B9 -> APALA YUJRA ROSELIN ANDREA | AI8: =IF(COUNTIF(C8:AH8,"A")=0,"",COUNTIF(C8:AH8,"A")) | AJ8: =IF(COUNTIF(C8:AH8,"F")=0,"",COUNTIF(C8:AH8,"F")) | AK8: =IF(COUNTIF(C8:AH8,"R")=0,"",COUNTIF(C8:AH8,"R")) | AL8: =IF(COUNTIF(C8:AH8,"L")=0,"",COUNTIF(C8:AH8,"L")) | AM8: =SUM(AI8:AL8) -> 0
A9: 2 | B9: =FILIACIÓN!$B10 -> APAZA ANGULO ARELY BIANCA | AI9: =IF(COUNTIF(C9:AH9,"A")=0,"",COUNTIF(C9:AH9,"A")) | AJ9: =IF(COUNTIF(C9:AH9,"F")=0,"",COUNTIF(C9:AH9,"F")) | AK9: =IF(COUNTIF(C9:AH9,"R")=0,"",COUNTIF(C9:AH9,"R")) | AL9: =IF(COUNTIF(C9:AH9,"L")=0,"",COUNTIF(C9:AH9,"L")) | AM9: =SUM(AI9:AL9) -> 0
A10: 3 | B10: =FILIACIÓN!$B11 -> APAZA TICONA DANAE ALEXANDRA | AI10: =IF(COUNTIF(C10:AH10,"A")=0,"",COUNTIF(C10:AH10,"A")) | AJ10: =IF(COUNTIF(C10:AH10,"F")=0,"",COUNTIF(C10:AH10,"F")) | AK10: =IF(COUNTIF(C10:AH10,"R")=0,"",COUNTIF(C10:AH10,"R")) | AL10: =IF(COUNTIF(C10:AH10,"L")=0,"",COUNTIF(C10:AH10,"L")) | AM10: =SUM(AI10:AL10) -> 0
A11: 4 | B11: =FILIACIÓN!$B12 -> ARDORES USNAYO CAMERON GAELLE | AI11: =IF(COUNTIF(C11:AH11,"A")=0,"",COUNTIF(C11:AH11,"A")) | AJ11: =IF(COUNTIF(C11:AH11,"F")=0,"",COUNTIF(C11:AH11,"F")) | AK11: =IF(COUNTIF(C11:AH11,"R")=0,"",COUNTIF(C11:AH11,"R")) | AL11: =IF(COUNTIF(C11:AH11,"L")=0,"",COUNTIF(C11:AH11,"L")) | AM11: =SUM(AI11:AL11) -> 0
A12: 5 | B12: =FILIACIÓN!$B13 -> BAUTISTA BLANCO GREIS EVANI | AI12: =IF(COUNTIF(C12:AH12,"A")=0,"",COUNTIF(C12:AH12,"A")) | AJ12: =IF(COUNTIF(C12:AH12,"F")=0,"",COUNTIF(C12:AH12,"F")) | AK12: =IF(COUNTIF(C12:AH12,"R")=0,"",COUNTIF(C12:AH12,"R")) | AL12: =IF(COUNTIF(C12:AH12,"L")=0,"",COUNTIF(C12:AH12,"L")) | AM12: =SUM(AI12:AL12) -> 0
A13: 6 | B13: =FILIACIÓN!$B14 -> CACERES FLORES KIMBERLY AVRIL | AI13: =IF(COUNTIF(C13:AH13,"A")=0,"",COUNTIF(C13:AH13,"A")) | AJ13: =IF(COUNTIF(C13:AH13,"F")=0,"",COUNTIF(C13:AH13,"F")) | AK13: =IF(COUNTIF(C13:AH13,"R")=0,"",COUNTIF(C13:AH13,"R")) | AL13: =IF(COUNTIF(C13:AH13,"L")=0,"",COUNTIF(C13:AH13,"L")) | AM13: =SUM(AI13:AL13) -> 0
A14: 7 | B14: =FILIACIÓN!$B15 -> CALLE MARQUEZ SOL MADELEY | AI14: =IF(COUNTIF(C14:AH14,"A")=0,"",COUNTIF(C14:AH14,"A")) | AJ14: =IF(COUNTIF(C14:AH14,"F")=0,"",COUNTIF(C14:AH14,"F")) | AK14: =IF(COUNTIF(C14:AH14,"R")=0,"",COUNTIF(C14:AH14,"R")) | AL14: =IF(COUNTIF(C14:AH14,"L")=0,"",COUNTIF(C14:AH14,"L")) | AM14: =SUM(AI14:AL14) -> 0
A15: 8 | B15: =FILIACIÓN!$B16 -> CALLISAYA CORONEL BELLA LUZ JAEL | AI15: =IF(COUNTIF(C15:AH15,"A")=0,"",COUNTIF(C15:AH15,"A")) | AJ15: =IF(COUNTIF(C15:AH15,"F")=0,"",COUNTIF(C15:AH15,"F")) | AK15: =IF(COUNTIF(C15:AH15,"R")=0,"",COUNTIF(C15:AH15,"R")) | AL15: =IF(COUNTIF(C15:AH15,"L")=0,"",COUNTIF(C15:AH15,"L")) | AM15: =SUM(AI15:AL15) -> 0
A16: 9 | B16: =FILIACIÓN!$B17 -> CALLISAYA CRUZ CAMILA RIZEL | AI16: =IF(COUNTIF(C16:AH16,"A")=0,"",COUNTIF(C16:AH16,"A")) | AJ16: =IF(COUNTIF(C16:AH16,"F")=0,"",COUNTIF(C16:AH16,"F")) | AK16: =IF(COUNTIF(C16:AH16,"R")=0,"",COUNTIF(C16:AH16,"R")) | AL16: =IF(COUNTIF(C16:AH16,"L")=0,"",COUNTIF(C16:AH16,"L")) | AM16: =SUM(AI16:AL16) -> 0
A17: 10 | B17: =FILIACIÓN!$B18 -> CHARCAS COLQUE ALEJANDRA BRIDGET | AI17: =IF(COUNTIF(C17:AH17,"A")=0,"",COUNTIF(C17:AH17,"A")) | AJ17: =IF(COUNTIF(C17:AH17,"F")=0,"",COUNTIF(C17:AH17,"F")) | AK17: =IF(COUNTIF(C17:AH17,"R")=0,"",COUNTIF(C17:AH17,"R")) | AL17: =IF(COUNTIF(C17:AH17,"L")=0,"",COUNTIF(C17:AH17,"L")) | AM17: =SUM(AI17:AL17) -> 0
A18: 11 | B18: =FILIACIÓN!$B19 -> CONDORI CHOQUE SAYUMI | AI18: =IF(COUNTIF(C18:AH18,"A")=0,"",COUNTIF(C18:AH18,"A")) | AJ18: =IF(COUNTIF(C18:AH18,"F")=0,"",COUNTIF(C18:AH18,"F")) | AK18: =IF(COUNTIF(C18:AH18,"R")=0,"",COUNTIF(C18:AH18,"R")) | AL18: =IF(COUNTIF(C18:AH18,"L")=0,"",COUNTIF(C18:AH18,"L")) | AM18: =SUM(AI18:AL18) -> 0
A19: 12 | B19: =FILIACIÓN!$B20 -> CONDORI MARQUEZ JHUREM ALEX | AI19: =IF(COUNTIF(C19:AH19,"A")=0,"",COUNTIF(C19:AH19,"A")) | AJ19: =IF(COUNTIF(C19:AH19,"F")=0,"",COUNTIF(C19:AH19,"F")) | AK19: =IF(COUNTIF(C19:AH19,"R")=0,"",COUNTIF(C19:AH19,"R")) | AL19: =IF(COUNTIF(C19:AH19,"L")=0,"",COUNTIF(C19:AH19,"L")) | AM19: =SUM(AI19:AL19) -> 0
... A43: 36 | B43: =FILIACIÓN!$B44 -> 0 | AI43: =IF(COUNTIF(C43:AH43,"A")=0,"",COUNTIF(C43:AH43,"A")) | AJ43: =IF(COUNTIF(C43:AH43,"F")=0,"",COUNTIF(C43:AH43,"F")) | AK43: =IF(COUNTIF(C43:AH43,"R")=0,"",COUNTIF(C43:AH43,"R")) | AL43: =IF(COUNTIF(C43:AH43,"L")=0,"",COUNTIF(C43:AH43,"L")) | AM43: =SUM(AI43:AL43) -> 0

Sheet ASIS 3 TRIM
A1: CONTROL DE ASISTENCIA 3º TRIMESTRE
B3: UNIDAD EDUCATIVA | C3: =CARÁTULA!$C$10 -> INTERANDINO BOLIVIANO
B4: NIVEL | C4: =CARÁTULA!$C$16 -> SECUNDARIO | R4: INICIO TRIMESTRE | AB4: =CARÁTULA!H21 -> 46266 | AI4: TRIMESTRE
B5: GRADO | C5: =CARÁTULA!$C$18 -> 5° "A" DE SECUNDARIA | R5: FIN TRIMESTRE | AB5: =CARÁTULA!J21 -> 46358 | AI5: 3er.
B6: DOCENTE | C6: =CARÁTULA!$C$14 -> MARCO A. CHAVEZ CHOQUEHUANCA | R6: FECHA ACTUAL | AB6: =TODAY() -> 46138
A7: Nº | B7: NÓMINA DE ESTUDIANTES Apellidos y Nombres | C7: 45694 | D7: 45701 | E7: 45708 | F7: 45715 | G7: 45722 | H7: 45729 | I7: 45736 | J7: 45743 | K7: 45750 | L7: 45757 | M7: 45764 | N7: 45771 | O7: 45778 | P7: 45785 | AI7: Asist. (A) | AJ7: Faltas (F) | AK7: Retrasos (R) | AL7: Licencias (L) | AM7: DÍAS TRABAJADOS
A8: 1 | B8: =FILIACIÓN!$B9 -> APALA YUJRA ROSELIN ANDREA | AI8: =IF(COUNTIF(C8:AH8,"A")=0,"",COUNTIF(C8:AH8,"A")) | AJ8: =IF(COUNTIF(C8:AH8,"F")=0,"",COUNTIF(C8:AH8,"F")) | AK8: =IF(COUNTIF(C8:AH8,"R")=0,"",COUNTIF(C8:AH8,"R")) | AL8: =IF(COUNTIF(C8:AH8,"L")=0,"",COUNTIF(C8:AH8,"L")) | AM8: =SUM(AI8:AL8) -> 0
A9: 2 | B9: =FILIACIÓN!$B10 -> APAZA ANGULO ARELY BIANCA | AI9: =IF(COUNTIF(C9:AH9,"A")=0,"",COUNTIF(C9:AH9,"A")) | AJ9: =IF(COUNTIF(C9:AH9,"F")=0,"",COUNTIF(C9:AH9,"F")) | AK9: =IF(COUNTIF(C9:AH9,"R")=0,"",COUNTIF(C9:AH9,"R")) | AL9: =IF(COUNTIF(C9:AH9,"L")=0,"",COUNTIF(C9:AH9,"L")) | AM9: =SUM(AI9:AL9) -> 0
A10: 3 | B10: =FILIACIÓN!$B11 -> APAZA TICONA DANAE ALEXANDRA | AI10: =IF(COUNTIF(C10:AH10,"A")=0,"",COUNTIF(C10:AH10,"A")) | AJ10: =IF(COUNTIF(C10:AH10,"F")=0,"",COUNTIF(C10:AH10,"F")) | AK10: =IF(COUNTIF(C10:AH10,"R")=0,"",COUNTIF(C10:AH10,"R")) | AL10: =IF(COUNTIF(C10:AH10,"L")=0,"",COUNTIF(C10:AH10,"L")) | AM10: =SUM(AI10:AL10) -> 0
A11: 4 | B11: =FILIACIÓN!$B12 -> ARDORES USNAYO CAMERON GAELLE | AI11: =IF(COUNTIF(C11:AH11,"A")=0,"",COUNTIF(C11:AH11,"A")) | AJ11: =IF(COUNTIF(C11:AH11,"F")=0,"",COUNTIF(C11:AH11,"F")) | AK11: =IF(COUNTIF(C11:AH11,"R")=0,"",COUNTIF(C11:AH11,"R")) | AL11: =IF(COUNTIF(C11:AH11,"L")=0,"",COUNTIF(C11:AH11,"L")) | AM11: =SUM(AI11:AL11) -> 0
A12: 5 | B12: =FILIACIÓN!$B13 -> BAUTISTA BLANCO GREIS EVANI | AI12: =IF(COUNTIF(C12:AH12,"A")=0,"",COUNTIF(C12:AH12,"A")) | AJ12: =IF(COUNTIF(C12:AH12,"F")=0,"",COUNTIF(C12:AH12,"F")) | AK12: =IF(COUNTIF(C12:AH12,"R")=0,"",COUNTIF(C12:AH12,"R")) | AL12: =IF(COUNTIF(C12:AH12,"L")=0,"",COUNTIF(C12:AH12,"L")) | AM12: =SUM(AI12:AL12) -> 0
A13: 6 | B13: =FILIACIÓN!$B14 -> CACERES FLORES KIMBERLY AVRIL | AI13: =IF(COUNTIF(C13:AH13,"A")=0,"",COUNTIF(C13:AH13,"A")) | AJ13: =IF(COUNTIF(C13:AH13,"F")=0,"",COUNTIF(C13:AH13,"F")) | AK13: =IF(COUNTIF(C13:AH13,"R")=0,"",COUNTIF(C13:AH13,"R")) | AL13: =IF(COUNTIF(C13:AH13,"L")=0,"",COUNTIF(C13:AH13,"L")) | AM13: =SUM(AI13:AL13) -> 0
A14: 7 | B14: =FILIACIÓN!$B15 -> CALLE MARQUEZ SOL MADELEY | AI14: =IF(COUNTIF(C14:AH14,"A")=0,"",COUNTIF(C14:AH14,"A")) | AJ14: =IF(COUNTIF(C14:AH14,"F")=0,"",COUNTIF(C14:AH14,"F")) | AK14: =IF(COUNTIF(C14:AH14,"R")=0,"",COUNTIF(C14:AH14,"R")) | AL14: =IF(COUNTIF(C14:AH14,"L")=0,"",COUNTIF(C14:AH14,"L")) | AM14: =SUM(AI14:AL14) -> 0
A15: 8 | B15: =FILIACIÓN!$B16 -> CALLISAYA CORONEL BELLA LUZ JAEL | AI15: =IF(COUNTIF(C15:AH15,"A")=0,"",COUNTIF(C15:AH15,"A")) | AJ15: =IF(COUNTIF(C15:AH15,"F")=0,"",COUNTIF(C15:AH15,"F")) | AK15: =IF(COUNTIF(C15:AH15,"R")=0,"",COUNTIF(C15:AH15,"R")) | AL15: =IF(COUNTIF(C15:AH15,"L")=0,"",COUNTIF(C15:AH15,"L")) | AM15: =SUM(AI15:AL15) -> 0
A16: 9 | B16: =FILIACIÓN!$B17 -> CALLISAYA CRUZ CAMILA RIZEL | AI16: =IF(COUNTIF(C16:AH16,"A")=0,"",COUNTIF(C16:AH16,"A")) | AJ16: =IF(COUNTIF(C16:AH16,"F")=0,"",COUNTIF(C16:AH16,"F")) | AK16: =IF(COUNTIF(C16:AH16,"R")=0,"",COUNTIF(C16:AH16,"R")) | AL16: =IF(COUNTIF(C16:AH16,"L")=0,"",COUNTIF(C16:AH16,"L")) | AM16: =SUM(AI16:AL16) -> 0
A17: 10 | B17: =FILIACIÓN!$B18 -> CHARCAS COLQUE ALEJANDRA BRIDGET | AI17: =IF(COUNTIF(C17:AH17,"A")=0,"",COUNTIF(C17:AH17,"A")) | AJ17: =IF(COUNTIF(C17:AH17,"F")=0,"",COUNTIF(C17:AH17,"F")) | AK17: =IF(COUNTIF(C17:AH17,"R")=0,"",COUNTIF(C17:AH17,"R")) | AL17: =IF(COUNTIF(C17:AH17,"L")=0,"",COUNTIF(C17:AH17,"L")) | AM17: =SUM(AI17:AL17) -> 0
A18: 11 | B18: =FILIACIÓN!$B19 -> CONDORI CHOQUE SAYUMI | AI18: =IF(COUNTIF(C18:AH18,"A")=0,"",COUNTIF(C18:AH18,"A")) | AJ18: =IF(COUNTIF(C18:AH18,"F")=0,"",COUNTIF(C18:AH18,"F")) | AK18: =IF(COUNTIF(C18:AH18,"R")=0,"",COUNTIF(C18:AH18,"R")) | AL18: =IF(COUNTIF(C18:AH18,"L")=0,"",COUNTIF(C18:AH18,"L")) | AM18: =SUM(AI18:AL18) -> 0
A19: 12 | B19: =FILIACIÓN!$B20 -> CONDORI MARQUEZ JHUREM ALEX | AI19: =IF(COUNTIF(C19:AH19,"A")=0,"",COUNTIF(C19:AH19,"A")) | AJ19: =IF(COUNTIF(C19:AH19,"F")=0,"",COUNTIF(C19:AH19,"F")) | AK19: =IF(COUNTIF(C19:AH19,"R")=0,"",COUNTIF(C19:AH19,"R")) | AL19: =IF(COUNTIF(C19:AH19,"L")=0,"",COUNTIF(C19:AH19,"L")) | AM19: =SUM(AI19:AL19) -> 0
... A43: 36 | B43: =FILIACIÓN!$B44 -> 0 | AI43: =IF(COUNTIF(C43:AH43,"A")=0,"",COUNTIF(C43:AH43,"A")) | AJ43: =IF(COUNTIF(C43:AH43,"F")=0,"",COUNTIF(C43:AH43,"F")) | AK43: =IF(COUNTIF(C43:AH43,"R")=0,"",COUNTIF(C43:AH43,"R")) | AL43: =IF(COUNTIF(C43:AH43,"L")=0,"",COUNTIF(C43:AH43,"L")) | AM43: =SUM(AI43:AL43) -> 0

Sheet 1 TRIM
C2: REGISTRO DE VALORACIÓN 1º TRIMESTRE | AG2: TRIMESTRE | AI2: 1er.
B4: UNIDAD EDUCATIVA | C4: =CARÁTULA!$C$10 -> INTERANDINO BOLIVIANO | S4: ÁREA | T4: =CARÁTULA!C20 -> CIENCIAS SOCIALES | AD4: INICIO TRIMESTRE | AE4: =CARÁTULA!H11 -> 46055 | AJ4: ED | AK4: =COUNTIF(AE11:AE46,"ED") -> 0
B5: NIVEL | C5: =CARÁTULA!$C$16 -> SECUNDARIO | S5: DOCENTE | T5: =CARÁTULA!$C$14 -> MARCO A. CHAVEZ CHOQUEHUANCA | AD5: FIN TRIMESTRE | AE5: =CARÁTULA!J11 -> 46150 | AJ5: DA | AK5: =COUNTIF(AE11:AE46,"DA") -> 0
B6: GRADO | C6: =CARÁTULA!$C$18 -> 5° "A" DE SECUNDARIA | AD6: FECHA ACTUAL | AE6: =TODAY() -> 46138 | AJ6: DO | AK6: =COUNTIF(AE11:AE46,"DO") -> 13
AJ7: DP | AK7: =COUNTIF(AE11:AE46,"DP") -> 21
C8: EVALUACIÓN DEL MAESTRO
C9: SER/10 | G9: PROMEDIO SER | H9: SABER/45 | R9: PROMEDIO | S9: HACER/40 | AC9: PROMEDIO | AD9: AUTOEVALUACIÓN | AE9: RANGOS | AG9: PROM. TRIMEST. | AH9: SITUACIÓN TRIMESTRAL DEL/A ESTUDIANTE
A10: Nº | B10: NÓMINA DE ESTUDIANTES | C10: RESPETO | D10: RESPONSABILIDAD | E10: PUNTUALIDAD | H10: Parcial trimestre | I10: Examen trimestre | J10: CONTROL - LECTURA | K10: C.P.E. | L10: EVALUACION ORAL | S10: TEMA 1 - ACT. 1 | T10: TEMA 2 - ACT. 2 | U10: TEMA 3 - ACT. 3 | V10: ANALISIS | W10: TEMA 4 - ACT. 4-5 | X10: ACTIVIDAD QR.
A11: 1 | B11: =FILIACIÓN!B9 -> APALA YUJRA ROSELIN ANDREA | C11: 8 | D11: 9 | E11: 8 | G11: =IFERROR(ROUND(AVERAGE(C11:F11),0),"") -> 8 | H11: 39 | I11: 38 | J11: 39 | K11: 38 | L11: 45 | R11: =IFERROR(ROUND(AVERAGE(H11:Q11),0),"") -> 40 | S11: 35 | T11: 35 | U11: 30 | V11: 36 | W11: 40 | X11: 36 | AC11: =IFERROR(ROUND(AVERAGE(S11:AB11),0),"") -> 35 | AD11: 5 | AE11: =IF(AG11<20," ",IF(AG11<51,"ED",IF(AG11<67,"DA",IF(AG11<85,"DO","DP")))) -> DP | AG11: =IFERROR((SUM(G11,R11,AC11,AD11,AF11)),"") -> 88 | AH11: =IF(AG11="","",(IF(AND(AG11>=1,AG11<=50.499),"REPROBADO",IF(AND(AG11>=50.5,AG11<=100),"APROBADO")))) -> APROBADO
A12: 2 | B12: =FILIACIÓN!B10 -> APAZA ANGULO ARELY BIANCA | C12: 8 | D12: 8 | E12: 8 | G12: =IFERROR(ROUND(AVERAGE(C12:F12),0),"") -> 8 | H12: 40 | I12: 40 | J12: 26 | K12: 35 | L12: 45 | R12: =IFERROR(ROUND(AVERAGE(H12:Q12),0),"") -> 37 | S12: 36 | T12: 35 | U12: 35 | V12: 35 | W12: 38 | X12: 36 | AC12: =IFERROR(ROUND(AVERAGE(S12:AB12),0),"") -> 36 | AD12: 5 | AE12: =IF(AG12<20," ",IF(AG12<51,"ED",IF(AG12<67,"DA",IF(AG12<85,"DO","DP")))) -> DP | AG12: =IFERROR((SUM(G12,R12,AC12,AD12,AF12)),"") -> 86 | AH12: =IF(AG12="","",(IF(AND(AG12>=1,AG12<=50.499),"REPROBADO",IF(AND(AG12>=50.5,AG12<=100),"APROBADO")))) -> APROBADO
A13: 3 | B13: =FILIACIÓN!B11 -> APAZA TICONA DANAE ALEXANDRA | C13: 9 | D13: 7 | E13: 8 | G13: =IFERROR(ROUND(AVERAGE(C13:F13),0),"") -> 8 | H13: 44 | I13: 44 | J13: 21 | K13: 35 | L13: 45 | R13: =IFERROR(ROUND(AVERAGE(H13:Q13),0),"") -> 38 | S13: 30 | T13: 35 | U13: 30 | V13: 28 | W13: 38 | X13: 36 | AC13: =IFERROR(ROUND(AVERAGE(S13:AB13),0),"") -> 33 | AD13: 4 | AE13: =IF(AG13<20," ",IF(AG13<51,"ED",IF(AG13<67,"DA",IF(AG13<85,"DO","DP")))) -> DO | AG13: =IFERROR((SUM(G13,R13,AC13,AD13,AF13)),"") -> 83 | AH13: =IF(AG13="","",(IF(AND(AG13>=1,AG13<=50.499),"REPROBADO",IF(AND(AG13>=50.5,AG13<=100),"APROBADO")))) -> APROBADO
A14: 4 | B14: =FILIACIÓN!B12 -> ARDORES USNAYO CAMERON GAELLE | C14: 9 | D14: 9 | E14: 8 | G14: =IFERROR(ROUND(AVERAGE(C14:F14),0),"") -> 9 | H14: 45 | I14: 44 | J14: 43 | K14: 35 | L14: 42 | R14: =IFERROR(ROUND(AVERAGE(H14:Q14),0),"") -> 42 | S14: 30 | T14: 33 | U14: 38 | V14: 35 | W14: 40 | X14: 36 | AC14: =IFERROR(ROUND(AVERAGE(S14:AB14),0),"") -> 35 | AD14: 5 | AE14: =IF(AG14<20," ",IF(AG14<51,"ED",IF(AG14<67,"DA",IF(AG14<85,"DO","DP")))) -> DP | AG14: =IFERROR((SUM(G14,R14,AC14,AD14,AF14)),"") -> 91 | AH14: =IF(AG14="","",(IF(AND(AG14>=1,AG14<=50.499),"REPROBADO",IF(AND(AG14>=50.5,AG14<=100),"APROBADO")))) -> APROBADO
A15: 5 | B15: =FILIACIÓN!B13 -> BAUTISTA BLANCO GREIS EVANI | C15: 9 | D15: 9 | E15: 9 | G15: =IFERROR(ROUND(AVERAGE(C15:F15),0),"") -> 9 | H15: 43 | I15: 45 | J15: 37 | K15: 38 | L15: 30 | R15: =IFERROR(ROUND(AVERAGE(H15:Q15),0),"") -> 39 | S15: 36 | T15: 38 | U15: 36 | V15: 38 | W15: 40 | X15: 30 | AC15: =IFERROR(ROUND(AVERAGE(S15:AB15),0),"") -> 36 | AD15: 5 | AE15: =IF(AG15<20," ",IF(AG15<51,"ED",IF(AG15<67,"DA",IF(AG15<85,"DO","DP")))) -> DP | AG15: =IFERROR((SUM(G15,R15,AC15,AD15,AF15)),"") -> 89 | AH15: =IF(AG15="","",(IF(AND(AG15>=1,AG15<=50.499),"REPROBADO",IF(AND(AG15>=50.5,AG15<=100),"APROBADO")))) -> APROBADO
A16: 6 | B16: =FILIACIÓN!B14 -> CACERES FLORES KIMBERLY AVRIL | C16: 9 | D16: 9 | E16: 9 | G16: =IFERROR(ROUND(AVERAGE(C16:F16),0),"") -> 9 | H16: 42 | I16: 45 | J16: 43 | K16: 36 | L16: 45 | R16: =IFERROR(ROUND(AVERAGE(H16:Q16),0),"") -> 42 | S16: 36 | T16: 36 | U16: 36 | V16: 38 | W16: 40 | X16: 38 | AC16: =IFERROR(ROUND(AVERAGE(S16:AB16),0),"") -> 37 | AD16: 5 | AE16: =IF(AG16<20," ",IF(AG16<51,"ED",IF(AG16<67,"DA",IF(AG16<85,"DO","DP")))) -> DP | AG16: =IFERROR((SUM(G16,R16,AC16,AD16,AF16)),"") -> 93 | AH16: =IF(AG16="","",(IF(AND(AG16>=1,AG16<=50.499),"REPROBADO",IF(AND(AG16>=50.5,AG16<=100),"APROBADO")))) -> APROBADO
A17: 7 | B17: =FILIACIÓN!B15 -> CALLE MARQUEZ SOL MADELEY | C17: 8 | D17: 9 | E17: 9 | G17: =IFERROR(ROUND(AVERAGE(C17:F17),0),"") -> 9 | H17: 41 | I17: 40 | J17: 43 | K17: 35 | L17: 45 | R17: =IFERROR(ROUND(AVERAGE(H17:Q17),0),"") -> 41 | S17: 30 | T17: 33 | U17: 33 | V17: 35 | W17: 38 | X17: 38 | AC17: =IFERROR(ROUND(AVERAGE(S17:AB17),0),"") -> 35 | AD17: 5 | AE17: =IF(AG17<20," ",IF(AG17<51,"ED",IF(AG17<67,"DA",IF(AG17<85,"DO","DP")))) -> DP | AG17: =IFERROR((SUM(G17,R17,AC17,AD17,AF17)),"") -> 90 | AH17: =IF(AG17="","",(IF(AND(AG17>=1,AG17<=50.499),"REPROBADO",IF(AND(AG17>=50.5,AG17<=100),"APROBADO")))) -> APROBADO
A18: 8 | B18: =FILIACIÓN!B16 -> CALLISAYA CORONEL BELLA LUZ JAEL | C18: 9 | D18: 9 | E18: 8 | G18: =IFERROR(ROUND(AVERAGE(C18:F18),0),"") -> 9 | H18: 41 | I18: 45 | J18: 43 | K18: 38 | L18: 40 | R18: =IFERROR(ROUND(AVERAGE(H18:Q18),0),"") -> 41 | S18: 35 | T18: 35 | U18: 33 | V18: 35 | W18: 40 | X18: 38 | AC18: =IFERROR(ROUND(AVERAGE(S18:AB18),0),"") -> 36 | AD18: 5 | AE18: =IF(AG18<20," ",IF(AG18<51,"ED",IF(AG18<67,"DA",IF(AG18<85,"DO","DP")))) -> DP | AG18: =IFERROR((SUM(G18,R18,AC18,AD18,AF18)),"") -> 91 | AH18: =IF(AG18="","",(IF(AND(AG18>=1,AG18<=50.499),"REPROBADO",IF(AND(AG18>=50.5,AG18<=100),"APROBADO")))) -> APROBADO
A19: 9 | B19: =FILIACIÓN!B17 -> CALLISAYA CRUZ CAMILA RIZEL | C19: 9 | D19: 9 | E19: 9 | G19: =IFERROR(ROUND(AVERAGE(C19:F19),0),"") -> 9 | H19: 44 | I19: 45 | J19: 35 | K19: 38 | L19: 45 | R19: =IFERROR(ROUND(AVERAGE(H19:Q19),0),"") -> 41 | S19: 38 | T19: 40 | U19: 38 | V19: 40 | W19: 40 | X19: 38 | AC19: =IFERROR(ROUND(AVERAGE(S19:AB19),0),"") -> 39 | AD19: 5 | AE19: =IF(AG19<20," ",IF(AG19<51,"ED",IF(AG19<67,"DA",IF(AG19<85,"DO","DP")))) -> DP | AG19: =IFERROR((SUM(G19,R19,AC19,AD19,AF19)),"") -> 94 | AH19: =IF(AG19="","",(IF(AND(AG19>=1,AG19<=50.499),"REPROBADO",IF(AND(AG19>=50.5,AG19<=100),"APROBADO")))) -> APROBADO
A20: 10 | B20: =FILIACIÓN!B18 -> CHARCAS COLQUE ALEJANDRA BRIDGET | C20: 8 | D20: 9 | E20: 8 | G20: =IFERROR(ROUND(AVERAGE(C20:F20),0),"") -> 8 | H20: 33 | I20: 44 | J20: 41 | K20: 35 | L20: 40 | R20: =IFERROR(ROUND(AVERAGE(H20:Q20),0),"") -> 39 | S20: 33 | T20: 35 | U20: 35 | V20: 30 | W20: 40 | X20: 36 | AC20: =IFERROR(ROUND(AVERAGE(S20:AB20),0),"") -> 35 | AD20: 4 | AE20: =IF(AG20<20," ",IF(AG20<51,"ED",IF(AG20<67,"DA",IF(AG20<85,"DO","DP")))) -> DP | AG20: =IFERROR((SUM(G20,R20,AC20,AD20,AF20)),"") -> 86 | AH20: =IF(AG20="","",(IF(AND(AG20>=1,AG20<=50.499),"REPROBADO",IF(AND(AG20>=50.5,AG20<=100),"APROBADO")))) -> APROBADO
A21: 11 | B21: =FILIACIÓN!B19 -> CONDORI CHOQUE SAYUMI | C21: 8 | D21: 9 | E21: 9 | G21: =IFERROR(ROUND(AVERAGE(C21:F21),0),"") -> 9 | H21: 43 | I21: 44 | J21: 40 | K21: 35 | L21: 45 | R21: =IFERROR(ROUND(AVERAGE(H21:Q21),0),"") -> 41 | S21: 35 | T21: 38 | U21: 33 | V21: 28 | W21: 37 | X21: 36 | AC21: =IFERROR(ROUND(AVERAGE(S21:AB21),0),"") -> 35 | AD21: 5 | AE21: =IF(AG21<20," ",IF(AG21<51,"ED",IF(AG21<67,"DA",IF(AG21<85,"DO","DP")))) -> DP | AG21: =IFERROR((SUM(G21,R21,AC21,AD21,AF21)),"") -> 90 | AH21: =IF(AG21="","",(IF(AND(AG21>=1,AG21<=50.499),"REPROBADO",IF(AND(AG21>=50.5,AG21<=100),"APROBADO")))) -> APROBADO
A22: 12 | B22: =FILIACIÓN!B20 -> CONDORI MARQUEZ JHUREM ALEX | C22: 8 | D22: 9 | E22: 8 | G22: =IFERROR(ROUND(AVERAGE(C22:F22),0),"") -> 8 | H22: 39 | I22: 33 | J22: 25 | K22: 33 | L22: 35 | R22: =IFERROR(ROUND(AVERAGE(H22:Q22),0),"") -> 33 | S22: 30 | T22: 33 | U22: 35 | V22: 28 | W22: 40 | X22: 36 | AC22: =IFERROR(ROUND(AVERAGE(S22:AB22),0),"") -> 34 | AD22: 5 | AE22: =IF(AG22<20," ",IF(AG22<51,"ED",IF(AG22<67,"DA",IF(AG22<85,"DO","DP")))) -> DO | AG22: =IFERROR((SUM(G22,R22,AC22,AD22,AF22)),"") -> 80 | AH22: =IF(AG22="","",(IF(AND(AG22>=1,AG22<=50.499),"REPROBADO",IF(AND(AG22>=50.5,AG22<=100),"APROBADO")))) -> APROBADO
... A42: 32 | B42: =FILIACIÓN!B40 -> USNAYO ROJAS HUASCAR CRISTOPHER | C42: 8 | D42: 8 | E42: 8 | G42: =IFERROR(ROUND(AVERAGE(C42:F42),0),"") -> 8 | H42: 44 | I42: 33 | J42: 40 | K42: 35 | L42: 33 | R42: =IFERROR(ROUND(AVERAGE(H42:Q42),0),"") -> 37 | S42: 30 | T42: 30 | U42: 33 | V42: 33 | W42: 36 | X42: 36 | AC42: =IFERROR(ROUND(AVERAGE(S42:AB42),0),"") -> 33 | AD42: 3 | AE42: =IF(AG42<20," ",IF(AG42<51,"ED",IF(AG42<67,"DA",IF(AG42<85,"DO","DP")))) -> DO | AG42: =IFERROR((SUM(G42,R42,AC42,AD42,AF42)),"") -> 81 | AH42: =IF(AG42="","",(IF(AND(AG42>=1,AG42<=50.499),"REPROBADO",IF(AND(AG42>=50.5,AG42<=100),"APROBADO")))) -> APROBADO
A43: 33 | B43: =FILIACIÓN!B41 -> VEIZAGA YUJRA GIAN MEIJAN | C43: 8 | D43: 7 | E43: 7 | G43: =IFERROR(ROUND(AVERAGE(C43:F43),0),"") -> 7 | H43: 39 | J43: 45 | K43: 35 | L43: 33 | R43: =IFERROR(ROUND(AVERAGE(H43:Q43),0),"") -> 38 | S43: 30 | T43: 30 | U43: 28 | V43: 28 | W43: 20 | X43: 20 | AC43: =IFERROR(ROUND(AVERAGE(S43:AB43),0),"") -> 26 | AD43: 5 | AE43: =IF(AG43<20," ",IF(AG43<51,"ED",IF(AG43<67,"DA",IF(AG43<85,"DO","DP")))) -> DO | AG43: =IFERROR((SUM(G43,R43,AC43,AD43,AF43)),"") -> 76 | AH43: =IF(AG43="","",(IF(AND(AG43>=1,AG43<=50.499),"REPROBADO",IF(AND(AG43>=50.5,AG43<=100),"APROBADO")))) -> APROBADO
A44: 34 | B44: =FILIACIÓN!B42 -> VENTURA SALCEDO GABRIEL | C44: 9 | D44: 8 | E44: 8 | G44: =IFERROR(ROUND(AVERAGE(C44:F44),0),"") -> 8 | H44: 42 | I44: 41 | J44: 25 | K44: 35 | L44: 45 | R44: =IFERROR(ROUND(AVERAGE(H44:Q44),0),"") -> 38 | S44: 30 | T44: 33 | U44: 33 | V44: 30 | W44: 37 | X44: 36 | AC44: =IFERROR(ROUND(AVERAGE(S44:AB44),0),"") -> 33 | AD44: 5 | AE44: =IF(AG44<20," ",IF(AG44<51,"ED",IF(AG44<67,"DA",IF(AG44<85,"DO","DP")))) -> DO | AG44: =IFERROR((SUM(G44,R44,AC44,AD44,AF44)),"") -> 84 | AH44: =IF(AG44="","",(IF(AND(AG44>=1,AG44<=50.499),"REPROBADO",IF(AND(AG44>=50.5,AG44<=100),"APROBADO")))) -> APROBADO
A45: 35 | B45: =FILIACIÓN!B43 -> 0 | G45: =IFERROR(ROUND(AVERAGE(C45:F45),0),"") | R45: =IFERROR(ROUND(AVERAGE(H45:Q45),0),"") | AC45: =IFERROR(ROUND(AVERAGE(S45:AB45),0),"") | AD45: =IFERROR((AVERAGE(#REF!,#REF!)),"") | AE45: =IF(AG45<20," ",IF(AG45<51,"ED",IF(AG45<67,"DA",IF(AG45<85,"DO","DP")))) | AG45: =IFERROR((SUM(G45,R45,AC45,AD45,AF45)),"") -> 0 | AH45: =IF(AG45="","",(IF(AND(AG45>=1,AG45<=50.499),"REPROBADO",IF(AND(AG45>=50.5,AG45<=100),"APROBADO")))) -> FALSE
A46: 36 | B46: =FILIACIÓN!B44 -> 0 | G46: =IFERROR(ROUND(AVERAGE(C46:F46),0),"") | R46: =IFERROR(ROUND(AVERAGE(H46:Q46),0),"") | AC46: =IFERROR(ROUND(AVERAGE(S46:AB46),0),"") | AD46: =IFERROR((AVERAGE(#REF!,#REF!)),"") | AE46: =IF(AG46<20," ",IF(AG46<51,"ED",IF(AG46<67,"DA",IF(AG46<85,"DO","DP")))) | AG46: =IFERROR((SUM(G46,R46,AC46,AD46,AF46)),"") -> 0 | AH46: =IF(AG46="","",(IF(AND(AG46>=1,AG46<=50.499),"REPROBADO",IF(AND(AG46>=50.5,AG46<=100),"APROBADO")))) -> FALSE

Sheet CENTRAL 1 TRIM
B2: UNIDAD EDUCATIVA
B3: =CARÁTULA!$C$10 -> INTERANDINO BOLIVIANO
C4: ESTADO ACADÉMICO DE LOS ESTUDIANTES PRIMER TRIMESTRE
B5: ÁREA | C5: =CARÁTULA!$C$20 -> CIENCIAS SOCIALES | G5: GESTIÓN | H5: =CARÁTULA!$C$22 -> 2026
B6: DOCENTE | C6: =CARÁTULA!$C$14 -> MARCO A. CHAVEZ CHOQUEHUANCA | G6: CURSO | H6: =CARÁTULA!$C$18 -> 5° "A" DE SECUNDARIA
B8: NÓMINA DE ESTUDIANTES | C8: CALIFIC | D8: CONDICIÓN
A9: 1 | B9: =FILIACIÓN!B9 -> APALA YUJRA ROSELIN ANDREA | C9: =#REF! -> #REF! | D9: =IF(C9="","",(IF(AND(C9>=1,C9<=50.499),"REPROBADO",IF(AND(C9>=50.5,C9<=100),"APROBADO",IF(AND(C9<=0.5,C9<=0.5),"ABANDONO"))))) -> #REF!
A10: 2 | B10: =FILIACIÓN!B10 -> APAZA ANGULO ARELY BIANCA | C10: =#REF! -> #REF! | D10: =IF(C10="","",(IF(AND(C10>=1,C10<=50.499),"REPROBADO",IF(AND(C10>=50.5,C10<=100),"APROBADO",IF(AND(C10<=0.5,C10<=0.5),"ABANDONO"))))) -> #REF!
A11: 3 | B11: =FILIACIÓN!B11 -> APAZA TICONA DANAE ALEXANDRA | C11: =#REF! -> #REF! | D11: =IF(C11="","",(IF(AND(C11>=1,C11<=50.499),"REPROBADO",IF(AND(C11>=50.5,C11<=100),"APROBADO",IF(AND(C11<=0.5,C11<=0.5),"ABANDONO"))))) -> #REF!
A12: 4 | B12: =FILIACIÓN!B12 -> ARDORES USNAYO CAMERON GAELLE | C12: =#REF! -> #REF! | D12: =IF(C12="","",(IF(AND(C12>=1,C12<=50.499),"REPROBADO",IF(AND(C12>=50.5,C12<=100),"APROBADO",IF(AND(C12<=0.5,C12<=0.5),"ABANDONO"))))) -> #REF!
A13: 5 | B13: =FILIACIÓN!B29 -> LECOÑA ARRATIA MICHELLE | C13: =#REF! -> #REF! | D13: =IF(C13="","",(IF(AND(C13>=1,C13<=50.499),"REPROBADO",IF(AND(C13>=50.5,C13<=100),"APROBADO",IF(AND(C13<=0.5,C13<=0.5),"ABANDONO"))))) -> #REF!
A14: 6 | B14: =FILIACIÓN!B30 -> LLUPANQUE SELAEZ DEYVID ALEJANDRO | C14: =#REF! -> #REF! | D14: =IF(C14="","",(IF(AND(C14>=1,C14<=50.499),"REPROBADO",IF(AND(C14>=50.5,C14<=100),"APROBADO",IF(AND(C14<=0.5,C14<=0.5),"ABANDONO"))))) -> #REF!
A15: 7 | B15: =FILIACIÓN!B31 -> LOPEZ LIMA ASBEL | C15: =#REF! -> #REF! | D15: =IF(C15="","",(IF(AND(C15>=1,C15<=50.499),"REPROBADO",IF(AND(C15>=50.5,C15<=100),"APROBADO",IF(AND(C15<=0.5,C15<=0.5),"ABANDONO"))))) -> #REF!
A16: 8 | B16: =FILIACIÓN!B32 -> MAMANI PAUCARA NICOLE ALEXANDRA | C16: =#REF! -> #REF! | D16: =IF(C16="","",(IF(AND(C16>=1,C16<=50.499),"REPROBADO",IF(AND(C16>=50.5,C16<=100),"APROBADO",IF(AND(C16<=0.5,C16<=0.5),"ABANDONO"))))) -> #REF!
A17: 9 | B17: =FILIACIÓN!B33 -> MASCO AGUILAR BRIZIA ALISON | C17: =#REF! -> #REF! | D17: =IF(C17="","",(IF(AND(C17>=1,C17<=50.499),"REPROBADO",IF(AND(C17>=50.5,C17<=100),"APROBADO",IF(AND(C17<=0.5,C17<=0.5),"ABANDONO"))))) -> #REF!
A18: 10 | B18: =FILIACIÓN!B34 -> NINA CARATA LUIS FLAVIO | C18: =#REF! -> #REF! | D18: =IF(C18="","",(IF(AND(C18>=1,C18<=50.499),"REPROBADO",IF(AND(C18>=50.5,C18<=100),"APROBADO",IF(AND(C18<=0.5,C18<=0.5),"ABANDONO"))))) -> #REF!
A19: 11 | B19: =FILIACIÓN!B35 -> NINA YAHUINCHA EYDAN ENRRIQUE | C19: =#REF! -> #REF! | D19: =IF(C19="","",(IF(AND(C19>=1,C19<=50.499),"REPROBADO",IF(AND(C19>=50.5,C19<=100),"APROBADO",IF(AND(C19<=0.5,C19<=0.5),"ABANDONO"))))) -> #REF!
A20: 12 | B20: =FILIACIÓN!B36 -> PACO HUANCA HEYDI MIREYA | C20: =#REF! -> #REF! | D20: =IF(C20="","",(IF(AND(C20>=1,C20<=50.499),"REPROBADO",IF(AND(C20>=50.5,C20<=100),"APROBADO",IF(AND(C20<=0.5,C20<=0.5),"ABANDONO"))))) -> #REF!
A21: 13 | B21: =FILIACIÓN!B37 -> POCOMA VARGAS JOSUE ARMANDO | C21: =#REF! -> #REF! | D21: =IF(C21="","",(IF(AND(C21>=1,C21<=50.499),"REPROBADO",IF(AND(C21>=50.5,C21<=100),"APROBADO",IF(AND(C21<=0.5,C21<=0.5),"ABANDONO"))))) -> #REF!
A22: 14 | B22: =FILIACIÓN!B38 -> QUISPE HILARI PAOLA ARACELY | C22: =#REF! -> #REF! | D22: =IF(C22="","",(IF(AND(C22>=1,C22<=50.499),"REPROBADO",IF(AND(C22>=50.5,C22<=100),"APROBADO",IF(AND(C22<=0.5,C22<=0.5),"ABANDONO"))))) -> #REF!
A23: 15 | B23: =FILIACIÓN!B39 -> TORREZ QUISPE MAYRA ADRIANA | C23: =#REF! -> #REF! | D23: =IF(C23="","",(IF(AND(C23>=1,C23<=50.499),"REPROBADO",IF(AND(C23>=50.5,C23<=100),"APROBADO",IF(AND(C23<=0.5,C23<=0.5),"ABANDONO"))))) -> #REF!
A24: 16 | B24: =FILIACIÓN!B40 -> USNAYO ROJAS HUASCAR CRISTOPHER | C24: =#REF! -> #REF! | D24: =IF(C24="","",(IF(AND(C24>=1,C24<=50.499),"REPROBADO",IF(AND(C24>=50.5,C24<=100),"APROBADO",IF(AND(C24<=0.5,C24<=0.5),"ABANDONO"))))) -> #REF!
... A28: 20 | B28: =FILIACIÓN!B44 -> 0 | C28: =#REF! -> #REF! | D28: =IF(C28="","",(IF(AND(C28>=1,C28<=50.499),"REPROBADO",IF(AND(C28>=50.5,C28<=100),"APROBADO",IF(AND(C28<=0.5,C28<=0.5),"ABANDONO"))))) -> #REF!
A29: 21 | B29: =FILIACIÓN!#REF! -> #REF! | C29: =#REF! -> #REF! | D29: =IF(C29="","",(IF(AND(C29>=1,C29<=50.499),"REPROBADO",IF(AND(C29>=50.5,C29<=100),"APROBADO",IF(AND(C29<=0.5,C29<=0.5),"ABANDONO"))))) -> #REF!
A30: 22 | B30: =FILIACIÓN!#REF! -> #REF! | C30: =#REF! -> #REF! | D30: =IF(C30="","",(IF(AND(C30>=1,C30<=50.499),"REPROBADO",IF(AND(C30>=50.5,C30<=100),"APROBADO",IF(AND(C30<=0.5,C30<=0.5),"ABANDONO"))))) -> #REF!
A31: 23 | B31: =FILIACIÓN!#REF! -> #REF! | C31: =#REF! -> #REF! | D31: =IF(C31="","",(IF(AND(C31>=1,C31<=50.499),"REPROBADO",IF(AND(C31>=50.5,C31<=100),"APROBADO",IF(AND(C31<=0.5,C31<=0.5),"ABANDONO"))))) -> #REF!
A32: 24 | B32: =FILIACIÓN!#REF! -> #REF! | C32: =#REF! -> #REF! | D32: =IF(C32="","",(IF(AND(C32>=1,C32<=50.499),"REPROBADO",IF(AND(C32>=50.5,C32<=100),"APROBADO",IF(AND(C32<=0.5,C32<=0.5),"ABANDONO"))))) -> #REF!
A33: 25 | B33: =FILIACIÓN!#REF! -> #REF! | C33: =#REF! -> #REF! | D33: =IF(C33="","",(IF(AND(C33>=1,C33<=50.499),"REPROBADO",IF(AND(C33>=50.5,C33<=100),"APROBADO",IF(AND(C33<=0.5,C33<=0.5),"ABANDONO"))))) -> #REF!
A34: 26 | B34: =FILIACIÓN!#REF! -> #REF! | D34: =IF(C34="","",(IF(AND(C34>=1,C34<=50.499),"REPROBADO",IF(AND(C34>=50.5,C34<=100),"APROBADO",IF(AND(C34<=0.5,C34<=0.5),"ABANDONO")))))
A35: 27 | B35: =FILIACIÓN!#REF! -> #REF! | D35: =IF(C35="","",(IF(AND(C35>=1,C35<=50.499),"REPROBADO",IF(AND(C35>=50.5,C35<=100),"APROBADO",IF(AND(C35<=0.5,C35<=0.5),"ABANDONO")))))
A36: 28 | B36: =FILIACIÓN!#REF! -> #REF! | D36: =IF(C36="","",(IF(AND(C36>=1,C36<=50.499),"REPROBADO",IF(AND(C36>=50.5,C36<=100),"APROBADO",IF(AND(C36<=0.5,C36<=0.5),"ABANDONO")))))
A37: 29 | B37: =FILIACIÓN!#REF! -> #REF! | D37: =IF(C37="","",(IF(AND(C37>=1,C37<=50.499),"REPROBADO",IF(AND(C37>=50.5,C37<=100),"APROBADO",IF(AND(C37<=0.5,C37<=0.5),"ABANDONO"))))) | G37: Aprobados | H37: 13 | I37: =H37/$H$41 -> 0.54166667
A38: 30 | B38: =FILIACIÓN!#REF! -> #REF! | D38: =IF(C38="","",(IF(AND(C38>=1,C38<=50.499),"REPROBADO",IF(AND(C38>=50.5,C38<=100),"APROBADO",IF(AND(C38<=0.5,C38<=0.5),"ABANDONO"))))) | G38: Reprobados | H38: 4 | I38: =H38/$H$41 -> 0.16666667
A39: 31 | B39: =FILIACIÓN!#REF! -> #REF! | D39: =IF(C39="","",(IF(AND(C39>=1,C39<=50.499),"REPROBADO",IF(AND(C39>=50.5,C39<=100),"APROBADO",IF(AND(C39<=0.5,C39<=0.5),"ABANDONO"))))) | G39: Retirados | H39: 0 | I39: =H39/$H$41 -> 0
A40: 32 | B40: =FILIACIÓN!#REF! -> #REF! | D40: =IF(C40="","",(IF(AND(C40>=1,C40<=50.499),"REPROBADO",IF(AND(C40>=50.5,C40<=100),"APROBADO",IF(AND(C40<=0.5,C40<=0.5),"ABANDONO"))))) | G40: Abandonos | H40: 7 | I40: =H40/$H$41 -> 0.29166667
A41: 33 | B41: =FILIACIÓN!#REF! -> #REF! | D41: =IF(C41="","",(IF(AND(C41>=1,C41<=50.499),"REPROBADO",IF(AND(C41>=50.5,C41<=100),"APROBADO",IF(AND(C41<=0.5,C41<=0.5),"ABANDONO"))))) | G41: Total estudiantes | H41: =SUM(H37:H40) -> 24 | I41: =H41/$H$41 -> 1
A42: 34 | B42: =FILIACIÓN!#REF! -> #REF! | D42: =IF(C42="","",(IF(AND(C42>=1,C42<=50.499),"REPROBADO",IF(AND(C42>=50.5,C42<=100),"APROBADO",IF(AND(C42<=0.5,C42<=0.5),"ABANDONO")))))
A43: 35 | B43: =FILIACIÓN!#REF! -> #REF! | D43: =IF(C43="","",(IF(AND(C43>=1,C43<=50.499),"REPROBADO",IF(AND(C43>=50.5,C43<=100),"APROBADO",IF(AND(C43<=0.5,C43<=0.5),"ABANDONO")))))
A44: 36 | B44: =FILIACIÓN!#REF! -> #REF! | D44: =IF(C44="","",(IF(AND(C44>=1,C44<=50.499),"REPROBADO",IF(AND(C44>=50.5,C44<=100),"APROBADO",IF(AND(C44<=0.5,C44<=0.5),"ABANDONO")))))

Sheet CENTRAL 2 TRIM
B2: UNIDAD EDUCATIVA
B3: =CARÁTULA!$C$10 -> INTERANDINO BOLIVIANO
C4: ESTADO ACADÉMICO DE LOS ESTUDIANTES SEGUNDO TRIMESTRE
B5: ÁREA | C5: =CARÁTULA!$C$20 -> CIENCIAS SOCIALES | G5: GESTIÓN | H5: =CARÁTULA!$C$22 -> 2026
B6: DOCENTE | C6: =CARÁTULA!$C$14 -> MARCO A. CHAVEZ CHOQUEHUANCA | G6: CURSO | H6: =CARÁTULA!$C$18 -> 5° "A" DE SECUNDARIA
B8: NÓMINA DE ESTUDIANTES | C8: CALIFIC | D8: CONDICIÓN
A9: 1 | B9: =FILIACIÓN!B9 -> APALA YUJRA ROSELIN ANDREA | C9: =#REF! -> #REF! | D9: =IF(C9="","",(IF(AND(C9>=1,C9<=50.499),"REPROBADO",IF(AND(C9>=50.5,C9<=100),"APROBADO",IF(AND(C9<=0.5,C9<=0.5),"ABANDONO"))))) -> #REF!
A10: 2 | B10: =FILIACIÓN!B10 -> APAZA ANGULO ARELY BIANCA | C10: =#REF! -> #REF! | D10: =IF(C10="","",(IF(AND(C10>=1,C10<=50.499),"REPROBADO",IF(AND(C10>=50.5,C10<=100),"APROBADO",IF(AND(C10<=0.5,C10<=0.5),"ABANDONO"))))) -> #REF!
A11: 3 | B11: =FILIACIÓN!B11 -> APAZA TICONA DANAE ALEXANDRA | C11: =#REF! -> #REF! | D11: =IF(C11="","",(IF(AND(C11>=1,C11<=50.499),"REPROBADO",IF(AND(C11>=50.5,C11<=100),"APROBADO",IF(AND(C11<=0.5,C11<=0.5),"ABANDONO"))))) -> #REF!
A12: 4 | B12: =FILIACIÓN!B12 -> ARDORES USNAYO CAMERON GAELLE | C12: =#REF! -> #REF! | D12: =IF(C12="","",(IF(AND(C12>=1,C12<=50.499),"REPROBADO",IF(AND(C12>=50.5,C12<=100),"APROBADO",IF(AND(C12<=0.5,C12<=0.5),"ABANDONO"))))) -> #REF!
A13: 5 | B13: =FILIACIÓN!B29 -> LECOÑA ARRATIA MICHELLE | C13: =#REF! -> #REF! | D13: =IF(C13="","",(IF(AND(C13>=1,C13<=50.499),"REPROBADO",IF(AND(C13>=50.5,C13<=100),"APROBADO",IF(AND(C13<=0.5,C13<=0.5),"ABANDONO"))))) -> #REF!
A14: 6 | B14: =FILIACIÓN!B30 -> LLUPANQUE SELAEZ DEYVID ALEJANDRO | C14: =#REF! -> #REF! | D14: =IF(C14="","",(IF(AND(C14>=1,C14<=50.499),"REPROBADO",IF(AND(C14>=50.5,C14<=100),"APROBADO",IF(AND(C14<=0.5,C14<=0.5),"ABANDONO"))))) -> #REF!
A15: 7 | B15: =FILIACIÓN!B31 -> LOPEZ LIMA ASBEL | C15: =#REF! -> #REF! | D15: =IF(C15="","",(IF(AND(C15>=1,C15<=50.499),"REPROBADO",IF(AND(C15>=50.5,C15<=100),"APROBADO",IF(AND(C15<=0.5,C15<=0.5),"ABANDONO"))))) -> #REF!
A16: 8 | B16: =FILIACIÓN!B32 -> MAMANI PAUCARA NICOLE ALEXANDRA | C16: =#REF! -> #REF! | D16: =IF(C16="","",(IF(AND(C16>=1,C16<=50.499),"REPROBADO",IF(AND(C16>=50.5,C16<=100),"APROBADO",IF(AND(C16<=0.5,C16<=0.5),"ABANDONO"))))) -> #REF!
A17: 9 | B17: =FILIACIÓN!B33 -> MASCO AGUILAR BRIZIA ALISON | C17: =#REF! -> #REF! | D17: =IF(C17="","",(IF(AND(C17>=1,C17<=50.499),"REPROBADO",IF(AND(C17>=50.5,C17<=100),"APROBADO",IF(AND(C17<=0.5,C17<=0.5),"ABANDONO"))))) -> #REF!
A18: 10 | B18: =FILIACIÓN!B34 -> NINA CARATA LUIS FLAVIO | C18: =#REF! -> #REF! | D18: =IF(C18="","",(IF(AND(C18>=1,C18<=50.499),"REPROBADO",IF(AND(C18>=50.5,C18<=100),"APROBADO",IF(AND(C18<=0.5,C18<=0.5),"ABANDONO"))))) -> #REF!
A19: 11 | B19: =FILIACIÓN!B35 -> NINA YAHUINCHA EYDAN ENRRIQUE | C19: =#REF! -> #REF! | D19: =IF(C19="","",(IF(AND(C19>=1,C19<=50.499),"REPROBADO",IF(AND(C19>=50.5,C19<=100),"APROBADO",IF(AND(C19<=0.5,C19<=0.5),"ABANDONO"))))) -> #REF!
A20: 12 | B20: =FILIACIÓN!B36 -> PACO HUANCA HEYDI MIREYA | C20: =#REF! -> #REF! | D20: =IF(C20="","",(IF(AND(C20>=1,C20<=50.499),"REPROBADO",IF(AND(C20>=50.5,C20<=100),"APROBADO",IF(AND(C20<=0.5,C20<=0.5),"ABANDONO"))))) -> #REF!
A21: 13 | B21: =FILIACIÓN!B37 -> POCOMA VARGAS JOSUE ARMANDO | C21: =#REF! -> #REF! | D21: =IF(C21="","",(IF(AND(C21>=1,C21<=50.499),"REPROBADO",IF(AND(C21>=50.5,C21<=100),"APROBADO",IF(AND(C21<=0.5,C21<=0.5),"ABANDONO"))))) -> #REF!
A22: 14 | B22: =FILIACIÓN!B38 -> QUISPE HILARI PAOLA ARACELY | C22: =#REF! -> #REF! | D22: =IF(C22="","",(IF(AND(C22>=1,C22<=50.499),"REPROBADO",IF(AND(C22>=50.5,C22<=100),"APROBADO",IF(AND(C22<=0.5,C22<=0.5),"ABANDONO"))))) -> #REF!
A23: 15 | B23: =FILIACIÓN!B39 -> TORREZ QUISPE MAYRA ADRIANA | C23: =#REF! -> #REF! | D23: =IF(C23="","",(IF(AND(C23>=1,C23<=50.499),"REPROBADO",IF(AND(C23>=50.5,C23<=100),"APROBADO",IF(AND(C23<=0.5,C23<=0.5),"ABANDONO"))))) -> #REF!
A24: 16 | B24: =FILIACIÓN!B40 -> USNAYO ROJAS HUASCAR CRISTOPHER | C24: =#REF! -> #REF! | D24: =IF(C24="","",(IF(AND(C24>=1,C24<=50.499),"REPROBADO",IF(AND(C24>=50.5,C24<=100),"APROBADO",IF(AND(C24<=0.5,C24<=0.5),"ABANDONO"))))) -> #REF!
... A28: 20 | B28: =FILIACIÓN!B44 -> 0 | C28: =#REF! -> #REF! | D28: =IF(C28="","",(IF(AND(C28>=1,C28<=50.499),"REPROBADO",IF(AND(C28>=50.5,C28<=100),"APROBADO",IF(AND(C28<=0.5,C28<=0.5),"ABANDONO"))))) -> #REF!
A29: 21 | B29: =FILIACIÓN!#REF! -> #REF! | C29: =#REF! -> #REF! | D29: =IF(C29="","",(IF(AND(C29>=1,C29<=50.499),"REPROBADO",IF(AND(C29>=50.5,C29<=100),"APROBADO",IF(AND(C29<=0.5,C29<=0.5),"ABANDONO"))))) -> #REF!
A30: 22 | B30: =FILIACIÓN!#REF! -> #REF! | C30: =#REF! -> #REF! | D30: =IF(C30="","",(IF(AND(C30>=1,C30<=50.499),"REPROBADO",IF(AND(C30>=50.5,C30<=100),"APROBADO",IF(AND(C30<=0.5,C30<=0.5),"ABANDONO"))))) -> #REF!
A31: 23 | B31: =FILIACIÓN!#REF! -> #REF! | C31: =#REF! -> #REF! | D31: =IF(C31="","",(IF(AND(C31>=1,C31<=50.499),"REPROBADO",IF(AND(C31>=50.5,C31<=100),"APROBADO",IF(AND(C31<=0.5,C31<=0.5),"ABANDONO"))))) -> #REF!
A32: 24 | B32: =FILIACIÓN!#REF! -> #REF! | C32: =#REF! -> #REF! | D32: =IF(C32="","",(IF(AND(C32>=1,C32<=50.499),"REPROBADO",IF(AND(C32>=50.5,C32<=100),"APROBADO",IF(AND(C32<=0.5,C32<=0.5),"ABANDONO"))))) -> #REF!
A33: 25 | B33: =FILIACIÓN!#REF! -> #REF! | C33: =#REF! -> #REF! | D33: =IF(C33="","",(IF(AND(C33>=1,C33<=50.499),"REPROBADO",IF(AND(C33>=50.5,C33<=100),"APROBADO",IF(AND(C33<=0.5,C33<=0.5),"ABANDONO"))))) -> #REF!
A34: 26 | B34: =FILIACIÓN!#REF! -> #REF! | D34: =IF(C34="","",(IF(AND(C34>=1,C34<=50.499),"REPROBADO",IF(AND(C34>=50.5,C34<=100),"APROBADO",IF(AND(C34<=0.5,C34<=0.5),"ABANDONO")))))
A35: 27 | B35: =FILIACIÓN!#REF! -> #REF! | D35: =IF(C35="","",(IF(AND(C35>=1,C35<=50.499),"REPROBADO",IF(AND(C35>=50.5,C35<=100),"APROBADO",IF(AND(C35<=0.5,C35<=0.5),"ABANDONO")))))
A36: 28 | B36: =FILIACIÓN!#REF! -> #REF! | D36: =IF(C36="","",(IF(AND(C36>=1,C36<=50.499),"REPROBADO",IF(AND(C36>=50.5,C36<=100),"APROBADO",IF(AND(C36<=0.5,C36<=0.5),"ABANDONO")))))
A37: 29 | B37: =FILIACIÓN!#REF! -> #REF! | D37: =IF(C37="","",(IF(AND(C37>=1,C37<=50.499),"REPROBADO",IF(AND(C37>=50.5,C37<=100),"APROBADO",IF(AND(C37<=0.5,C37<=0.5),"ABANDONO"))))) | G37: Aprobados | H37: 13 | I37: =H37/$H$41 -> 0.54166667
A38: 30 | B38: =FILIACIÓN!#REF! -> #REF! | D38: =IF(C38="","",(IF(AND(C38>=1,C38<=50.499),"REPROBADO",IF(AND(C38>=50.5,C38<=100),"APROBADO",IF(AND(C38<=0.5,C38<=0.5),"ABANDONO"))))) | G38: Reprobados | H38: 4 | I38: =H38/$H$41 -> 0.16666667
A39: 31 | B39: =FILIACIÓN!#REF! -> #REF! | D39: =IF(C39="","",(IF(AND(C39>=1,C39<=50.499),"REPROBADO",IF(AND(C39>=50.5,C39<=100),"APROBADO",IF(AND(C39<=0.5,C39<=0.5),"ABANDONO"))))) | G39: Retirados | H39: 0 | I39: =H39/$H$41 -> 0
A40: 32 | B40: =FILIACIÓN!#REF! -> #REF! | D40: =IF(C40="","",(IF(AND(C40>=1,C40<=50.499),"REPROBADO",IF(AND(C40>=50.5,C40<=100),"APROBADO",IF(AND(C40<=0.5,C40<=0.5),"ABANDONO"))))) | G40: Abandonos | H40: 7 | I40: =H40/$H$41 -> 0.29166667
A41: 33 | B41: =FILIACIÓN!#REF! -> #REF! | D41: =IF(C41="","",(IF(AND(C41>=1,C41<=50.499),"REPROBADO",IF(AND(C41>=50.5,C41<=100),"APROBADO",IF(AND(C41<=0.5,C41<=0.5),"ABANDONO"))))) | G41: Total estudiantes | H41: =SUM(H37:H40) -> 24 | I41: =H41/$H$41 -> 1
A42: 34 | B42: =FILIACIÓN!#REF! -> #REF! | D42: =IF(C42="","",(IF(AND(C42>=1,C42<=50.499),"REPROBADO",IF(AND(C42>=50.5,C42<=100),"APROBADO",IF(AND(C42<=0.5,C42<=0.5),"ABANDONO")))))
A43: 35 | B43: =FILIACIÓN!#REF! -> #REF! | D43: =IF(C43="","",(IF(AND(C43>=1,C43<=50.499),"REPROBADO",IF(AND(C43>=50.5,C43<=100),"APROBADO",IF(AND(C43<=0.5,C43<=0.5),"ABANDONO")))))
A44: 36 | B44: =FILIACIÓN!#REF! -> #REF! | D44: =IF(C44="","",(IF(AND(C44>=1,C44<=50.499),"REPROBADO",IF(AND(C44>=50.5,C44<=100),"APROBADO",IF(AND(C44<=0.5,C44<=0.5),"ABANDONO")))))

Sheet CENTRAL 3 TRIM
B2: UNIDAD EDUCATIVA
B3: =CARÁTULA!$C$10 -> INTERANDINO BOLIVIANO
C4: ESTADO ACADÉMICO DE LOS ESTUDIANTES TERCER TRIMESTRE
B5: ÁREA | C5: =CARÁTULA!$C$20 -> CIENCIAS SOCIALES | G5: GESTIÓN | H5: =CARÁTULA!$C$22 -> 2026
B6: DOCENTE | C6: =CARÁTULA!$C$14 -> MARCO A. CHAVEZ CHOQUEHUANCA | G6: CURSO | H6: =CARÁTULA!$C$18 -> 5° "A" DE SECUNDARIA
B8: NÓMINA DE ESTUDIANTES | C8: CALIFIC | D8: CONDICIÓN
A9: 1 | B9: =FILIACIÓN!B9 -> APALA YUJRA ROSELIN ANDREA | C9: =#REF! -> #REF! | D9: =IF(C9="","",(IF(AND(C9>=1,C9<=50.499),"REPROBADO",IF(AND(C9>=50.5,C9<=100),"APROBADO",IF(AND(C9<=0.5,C9<=0.5),"ABANDONO"))))) -> #REF!
A10: 2 | B10: =FILIACIÓN!B10 -> APAZA ANGULO ARELY BIANCA | C10: =#REF! -> #REF! | D10: =IF(C10="","",(IF(AND(C10>=1,C10<=50.499),"REPROBADO",IF(AND(C10>=50.5,C10<=100),"APROBADO",IF(AND(C10<=0.5,C10<=0.5),"ABANDONO"))))) -> #REF!
A11: 3 | B11: =FILIACIÓN!B11 -> APAZA TICONA DANAE ALEXANDRA | C11: =#REF! -> #REF! | D11: =IF(C11="","",(IF(AND(C11>=1,C11<=50.499),"REPROBADO",IF(AND(C11>=50.5,C11<=100),"APROBADO",IF(AND(C11<=0.5,C11<=0.5),"ABANDONO"))))) -> #REF!
A12: 4 | B12: =FILIACIÓN!B12 -> ARDORES USNAYO CAMERON GAELLE | C12: =#REF! -> #REF! | D12: =IF(C12="","",(IF(AND(C12>=1,C12<=50.499),"REPROBADO",IF(AND(C12>=50.5,C12<=100),"APROBADO",IF(AND(C12<=0.5,C12<=0.5),"ABANDONO"))))) -> #REF!
A13: 5 | B13: =FILIACIÓN!B29 -> LECOÑA ARRATIA MICHELLE | C13: =#REF! -> #REF! | D13: =IF(C13="","",(IF(AND(C13>=1,C13<=50.499),"REPROBADO",IF(AND(C13>=50.5,C13<=100),"APROBADO",IF(AND(C13<=0.5,C13<=0.5),"ABANDONO"))))) -> #REF!
A14: 6 | B14: =FILIACIÓN!B30 -> LLUPANQUE SELAEZ DEYVID ALEJANDRO | C14: =#REF! -> #REF! | D14: =IF(C14="","",(IF(AND(C14>=1,C14<=50.499),"REPROBADO",IF(AND(C14>=50.5,C14<=100),"APROBADO",IF(AND(C14<=0.5,C14<=0.5),"ABANDONO"))))) -> #REF!
A15: 7 | B15: =FILIACIÓN!B31 -> LOPEZ LIMA ASBEL | C15: =#REF! -> #REF! | D15: =IF(C15="","",(IF(AND(C15>=1,C15<=50.499),"REPROBADO",IF(AND(C15>=50.5,C15<=100),"APROBADO",IF(AND(C15<=0.5,C15<=0.5),"ABANDONO"))))) -> #REF!
A16: 8 | B16: =FILIACIÓN!B32 -> MAMANI PAUCARA NICOLE ALEXANDRA | C16: =#REF! -> #REF! | D16: =IF(C16="","",(IF(AND(C16>=1,C16<=50.499),"REPROBADO",IF(AND(C16>=50.5,C16<=100),"APROBADO",IF(AND(C16<=0.5,C16<=0.5),"ABANDONO"))))) -> #REF!
A17: 9 | B17: =FILIACIÓN!B33 -> MASCO AGUILAR BRIZIA ALISON | C17: =#REF! -> #REF! | D17: =IF(C17="","",(IF(AND(C17>=1,C17<=50.499),"REPROBADO",IF(AND(C17>=50.5,C17<=100),"APROBADO",IF(AND(C17<=0.5,C17<=0.5),"ABANDONO"))))) -> #REF!
A18: 10 | B18: =FILIACIÓN!B34 -> NINA CARATA LUIS FLAVIO | C18: =#REF! -> #REF! | D18: =IF(C18="","",(IF(AND(C18>=1,C18<=50.499),"REPROBADO",IF(AND(C18>=50.5,C18<=100),"APROBADO",IF(AND(C18<=0.5,C18<=0.5),"ABANDONO"))))) -> #REF!
A19: 11 | B19: =FILIACIÓN!B35 -> NINA YAHUINCHA EYDAN ENRRIQUE | C19: =#REF! -> #REF! | D19: =IF(C19="","",(IF(AND(C19>=1,C19<=50.499),"REPROBADO",IF(AND(C19>=50.5,C19<=100),"APROBADO",IF(AND(C19<=0.5,C19<=0.5),"ABANDONO"))))) -> #REF!
A20: 12 | B20: =FILIACIÓN!B36 -> PACO HUANCA HEYDI MIREYA | C20: =#REF! -> #REF! | D20: =IF(C20="","",(IF(AND(C20>=1,C20<=50.499),"REPROBADO",IF(AND(C20>=50.5,C20<=100),"APROBADO",IF(AND(C20<=0.5,C20<=0.5),"ABANDONO"))))) -> #REF!
A21: 13 | B21: =FILIACIÓN!B37 -> POCOMA VARGAS JOSUE ARMANDO | C21: =#REF! -> #REF! | D21: =IF(C21="","",(IF(AND(C21>=1,C21<=50.499),"REPROBADO",IF(AND(C21>=50.5,C21<=100),"APROBADO",IF(AND(C21<=0.5,C21<=0.5),"ABANDONO"))))) -> #REF!
A22: 14 | B22: =FILIACIÓN!B38 -> QUISPE HILARI PAOLA ARACELY | C22: =#REF! -> #REF! | D22: =IF(C22="","",(IF(AND(C22>=1,C22<=50.499),"REPROBADO",IF(AND(C22>=50.5,C22<=100),"APROBADO",IF(AND(C22<=0.5,C22<=0.5),"ABANDONO"))))) -> #REF!
A23: 15 | B23: =FILIACIÓN!B39 -> TORREZ QUISPE MAYRA ADRIANA | C23: =#REF! -> #REF! | D23: =IF(C23="","",(IF(AND(C23>=1,C23<=50.499),"REPROBADO",IF(AND(C23>=50.5,C23<=100),"APROBADO",IF(AND(C23<=0.5,C23<=0.5),"ABANDONO"))))) -> #REF!
A24: 16 | B24: =FILIACIÓN!B40 -> USNAYO ROJAS HUASCAR CRISTOPHER | C24: =#REF! -> #REF! | D24: =IF(C24="","",(IF(AND(C24>=1,C24<=50.499),"REPROBADO",IF(AND(C24>=50.5,C24<=100),"APROBADO",IF(AND(C24<=0.5,C24<=0.5),"ABANDONO"))))) -> #REF!
... A28: 20 | B28: =FILIACIÓN!B44 -> 0 | C28: =#REF! -> #REF! | D28: =IF(C28="","",(IF(AND(C28>=1,C28<=50.499),"REPROBADO",IF(AND(C28>=50.5,C28<=100),"APROBADO",IF(AND(C28<=0.5,C28<=0.5),"ABANDONO"))))) -> #REF!
A29: 21 | B29: =FILIACIÓN!#REF! -> #REF! | C29: =#REF! -> #REF! | D29: =IF(C29="","",(IF(AND(C29>=1,C29<=50.499),"REPROBADO",IF(AND(C29>=50.5,C29<=100),"APROBADO",IF(AND(C29<=0.5,C29<=0.5),"ABANDONO"))))) -> #REF!
A30: 22 | B30: =FILIACIÓN!#REF! -> #REF! | C30: =#REF! -> #REF! | D30: =IF(C30="","",(IF(AND(C30>=1,C30<=50.499),"REPROBADO",IF(AND(C30>=50.5,C30<=100),"APROBADO",IF(AND(C30<=0.5,C30<=0.5),"ABANDONO"))))) -> #REF!
A31: 23 | B31: =FILIACIÓN!#REF! -> #REF! | C31: =#REF! -> #REF! | D31: =IF(C31="","",(IF(AND(C31>=1,C31<=50.499),"REPROBADO",IF(AND(C31>=50.5,C31<=100),"APROBADO",IF(AND(C31<=0.5,C31<=0.5),"ABANDONO"))))) -> #REF!
A32: 24 | B32: =FILIACIÓN!#REF! -> #REF! | C32: =#REF! -> #REF! | D32: =IF(C32="","",(IF(AND(C32>=1,C32<=50.499),"REPROBADO",IF(AND(C32>=50.5,C32<=100),"APROBADO",IF(AND(C32<=0.5,C32<=0.5),"ABANDONO"))))) -> #REF!
A33: 25 | B33: =FILIACIÓN!#REF! -> #REF! | C33: =#REF! -> #REF! | D33: =IF(C33="","",(IF(AND(C33>=1,C33<=50.499),"REPROBADO",IF(AND(C33>=50.5,C33<=100),"APROBADO",IF(AND(C33<=0.5,C33<=0.5),"ABANDONO"))))) -> #REF!
A34: 26 | B34: =FILIACIÓN!#REF! -> #REF! | D34: =IF(C34="","",(IF(AND(C34>=1,C34<=50.499),"REPROBADO",IF(AND(C34>=50.5,C34<=100),"APROBADO",IF(AND(C34<=0.5,C34<=0.5),"ABANDONO")))))
A35: 27 | B35: =FILIACIÓN!#REF! -> #REF! | D35: =IF(C35="","",(IF(AND(C35>=1,C35<=50.499),"REPROBADO",IF(AND(C35>=50.5,C35<=100),"APROBADO",IF(AND(C35<=0.5,C35<=0.5),"ABANDONO")))))
A36: 28 | B36: =FILIACIÓN!#REF! -> #REF! | D36: =IF(C36="","",(IF(AND(C36>=1,C36<=50.499),"REPROBADO",IF(AND(C36>=50.5,C36<=100),"APROBADO",IF(AND(C36<=0.5,C36<=0.5),"ABANDONO")))))
A37: 29 | B37: =FILIACIÓN!#REF! -> #REF! | D37: =IF(C37="","",(IF(AND(C37>=1,C37<=50.499),"REPROBADO",IF(AND(C37>=50.5,C37<=100),"APROBADO",IF(AND(C37<=0.5,C37<=0.5),"ABANDONO"))))) | G37: Aprobados | H37: 13 | I37: =H37/$H$41 -> 0.54166667
A38: 30 | B38: =FILIACIÓN!#REF! -> #REF! | D38: =IF(C38="","",(IF(AND(C38>=1,C38<=50.499),"REPROBADO",IF(AND(C38>=50.5,C38<=100),"APROBADO",IF(AND(C38<=0.5,C38<=0.5),"ABANDONO"))))) | G38: Reprobados | H38: 4 | I38: =H38/$H$41 -> 0.16666667
A39: 31 | B39: =FILIACIÓN!#REF! -> #REF! | D39: =IF(C39="","",(IF(AND(C39>=1,C39<=50.499),"REPROBADO",IF(AND(C39>=50.5,C39<=100),"APROBADO",IF(AND(C39<=0.5,C39<=0.5),"ABANDONO"))))) | G39: Retirados | H39: 0 | I39: =H39/$H$41 -> 0
A40: 32 | B40: =FILIACIÓN!#REF! -> #REF! | D40: =IF(C40="","",(IF(AND(C40>=1,C40<=50.499),"REPROBADO",IF(AND(C40>=50.5,C40<=100),"APROBADO",IF(AND(C40<=0.5,C40<=0.5),"ABANDONO"))))) | G40: Abandonos | H40: 7 | I40: =H40/$H$41 -> 0.29166667
A41: 33 | B41: =FILIACIÓN!#REF! -> #REF! | D41: =IF(C41="","",(IF(AND(C41>=1,C41<=50.499),"REPROBADO",IF(AND(C41>=50.5,C41<=100),"APROBADO",IF(AND(C41<=0.5,C41<=0.5),"ABANDONO"))))) | G41: Total estudiantes | H41: =SUM(H37:H40) -> 24 | I41: =H41/$H$41 -> 1
A42: 34 | B42: =FILIACIÓN!#REF! -> #REF! | D42: =IF(C42="","",(IF(AND(C42>=1,C42<=50.499),"REPROBADO",IF(AND(C42>=50.5,C42<=100),"APROBADO",IF(AND(C42<=0.5,C42<=0.5),"ABANDONO")))))
A43: 35 | B43: =FILIACIÓN!#REF! -> #REF! | D43: =IF(C43="","",(IF(AND(C43>=1,C43<=50.499),"REPROBADO",IF(AND(C43>=50.5,C43<=100),"APROBADO",IF(AND(C43<=0.5,C43<=0.5),"ABANDONO")))))
A44: 36 | B44: =FILIACIÓN!#REF! -> #REF! | D44: =IF(C44="","",(IF(AND(C44>=1,C44<=50.499),"REPROBADO",IF(AND(C44>=50.5,C44<=100),"APROBADO",IF(AND(C44<=0.5,C44<=0.5),"ABANDONO")))))

Sheet 2 TRIM
C2: REGISTRO DE VALORACIÓN 2º TRIMESTRE | AG2: TRIMESTRE | AI2: 2do.
B4: UNIDAD EDUCATIVA | C4: =CARÁTULA!$C$10 -> INTERANDINO BOLIVIANO | S4: ÁREA | T4: =CARÁTULA!C20 -> CIENCIAS SOCIALES | AD4: INICIO TRIMESTRE | AE4: =CARÁTULA!H16 -> 46153 | AJ4: ED | AK4: =COUNTIF(AE11:AE46,"ED") -> 0
B5: NIVEL | C5: =CARÁTULA!$C$16 -> SECUNDARIO | S5: DOCENTE | T5: =CARÁTULA!$C$14 -> MARCO A. CHAVEZ CHOQUEHUANCA | AD5: FIN TRIMESTRE | AE5: =CARÁTULA!J16 -> 46326 | AJ5: DA | AK5: =COUNTIF(AE11:AE46,"DA") -> 0
B6: GRADO | C6: =CARÁTULA!$C$18 -> 5° "A" DE SECUNDARIA | AD6: FECHA ACTUAL | AE6: =TODAY() -> 46138 | AJ6: DO | AK6: =COUNTIF(AE11:AE46,"DO") -> 0
AJ7: DP | AK7: =COUNTIF(AE11:AE46,"DP") -> 0
C8: EVALUACIÓN DEL MAESTRO
C9: SER/10 | G9: PROMEDIO SER | H9: SABER/45 | R9: PROMEDIO | S9: HACER/40 | AC9: PROMEDIO | AD9: AUTOEVALUACIÓN | AE9: RANGOS | AG9: PROM. TRIMEST. | AH9: SITUACIÓN TRIMESTRAL DEL/A ESTUDIANTE
A10: Nº | B10: NÓMINA DE ESTUDIANTES | C10: RESPETO | D10: RESPONSABILIDAD | E10: PUNTUALIDAD | H10: Parcial trimestre | I10: Examen trimestre
A11: 1 | B11: =FILIACIÓN!B9 -> APALA YUJRA ROSELIN ANDREA | G11: =IFERROR(ROUND(AVERAGE(C11:F11),0),"") | R11: =IFERROR(ROUND(AVERAGE(H11:Q11),0),"") | AC11: =IFERROR(ROUND(AVERAGE(S11:AB11),0),"") | AD11: =IFERROR((AVERAGE(#REF!,#REF!)),"") | AE11: =IF(AG11<20," ",IF(AG11<51,"ED",IF(AG11<67,"DA",IF(AG11<85,"DO","DP")))) | AG11: =IFERROR((SUM(G11,R11,AC11,AD11,AF11)),"") -> 0 | AH11: =IF(AG11="","",(IF(AND(AG11>=1,AG11<=50.499),"REPROBADO",IF(AND(AG11>=50.5,AG11<=100),"APROBADO")))) -> FALSE
A12: 2 | B12: =FILIACIÓN!B10 -> APAZA ANGULO ARELY BIANCA | G12: =IFERROR(ROUND(AVERAGE(C12:F12),0),"") | R12: =IFERROR(ROUND(AVERAGE(H12:Q12),0),"") | AC12: =IFERROR(ROUND(AVERAGE(S12:AB12),0),"") | AD12: =IFERROR((AVERAGE(#REF!,#REF!)),"") | AE12: =IF(AG12<20," ",IF(AG12<51,"ED",IF(AG12<67,"DA",IF(AG12<85,"DO","DP")))) | AG12: =IFERROR((SUM(G12,R12,AC12,AD12,AF12)),"") -> 0 | AH12: =IF(AG12="","",(IF(AND(AG12>=1,AG12<=50.499),"REPROBADO",IF(AND(AG12>=50.5,AG12<=100),"APROBADO")))) -> FALSE
A13: 3 | B13: =FILIACIÓN!B11 -> APAZA TICONA DANAE ALEXANDRA | G13: =IFERROR(ROUND(AVERAGE(C13:F13),0),"") | R13: =IFERROR(ROUND(AVERAGE(H13:Q13),0),"") | AC13: =IFERROR(ROUND(AVERAGE(S13:AB13),0),"") | AD13: =IFERROR((AVERAGE(#REF!,#REF!)),"") | AE13: =IF(AG13<20," ",IF(AG13<51,"ED",IF(AG13<67,"DA",IF(AG13<85,"DO","DP")))) | AG13: =IFERROR((SUM(G13,R13,AC13,AD13,AF13)),"") -> 0 | AH13: =IF(AG13="","",(IF(AND(AG13>=1,AG13<=50.499),"REPROBADO",IF(AND(AG13>=50.5,AG13<=100),"APROBADO")))) -> FALSE
A14: 4 | B14: =FILIACIÓN!B12 -> ARDORES USNAYO CAMERON GAELLE | G14: =IFERROR(ROUND(AVERAGE(C14:F14),0),"") | R14: =IFERROR(ROUND(AVERAGE(H14:Q14),0),"") | AC14: =IFERROR(ROUND(AVERAGE(S14:AB14),0),"") | AD14: =IFERROR((AVERAGE(#REF!,#REF!)),"") | AE14: =IF(AG14<20," ",IF(AG14<51,"ED",IF(AG14<67,"DA",IF(AG14<85,"DO","DP")))) | AG14: =IFERROR((SUM(G14,R14,AC14,AD14,AF14)),"") -> 0 | AH14: =IF(AG14="","",(IF(AND(AG14>=1,AG14<=50.499),"REPROBADO",IF(AND(AG14>=50.5,AG14<=100),"APROBADO")))) -> FALSE
A15: 5 | B15: =FILIACIÓN!B13 -> BAUTISTA BLANCO GREIS EVANI | G15: =IFERROR(ROUND(AVERAGE(C15:F15),0),"") | R15: =IFERROR(ROUND(AVERAGE(H15:Q15),0),"") | AC15: =IFERROR(ROUND(AVERAGE(S15:AB15),0),"") | AD15: =IFERROR((AVERAGE(#REF!,#REF!)),"") | AE15: =IF(AG15<20," ",IF(AG15<51,"ED",IF(AG15<67,"DA",IF(AG15<85,"DO","DP")))) | AG15: =IFERROR((SUM(G15,R15,AC15,AD15,AF15)),"") -> 0 | AH15: =IF(AG15="","",(IF(AND(AG15>=1,AG15<=50.499),"REPROBADO",IF(AND(AG15>=50.5,AG15<=100),"APROBADO")))) -> FALSE
A16: 6 | B16: =FILIACIÓN!B14 -> CACERES FLORES KIMBERLY AVRIL | G16: =IFERROR(ROUND(AVERAGE(C16:F16),0),"") | R16: =IFERROR(ROUND(AVERAGE(H16:Q16),0),"") | AC16: =IFERROR(ROUND(AVERAGE(S16:AB16),0),"") | AD16: =IFERROR((AVERAGE(#REF!,#REF!)),"") | AE16: =IF(AG16<20," ",IF(AG16<51,"ED",IF(AG16<67,"DA",IF(AG16<85,"DO","DP")))) | AG16: =IFERROR((SUM(G16,R16,AC16,AD16,AF16)),"") -> 0 | AH16: =IF(AG16="","",(IF(AND(AG16>=1,AG16<=50.499),"REPROBADO",IF(AND(AG16>=50.5,AG16<=100),"APROBADO")))) -> FALSE
A17: 7 | B17: =FILIACIÓN!B15 -> CALLE MARQUEZ SOL MADELEY | G17: =IFERROR(ROUND(AVERAGE(C17:F17),0),"") | R17: =IFERROR(ROUND(AVERAGE(H17:Q17),0),"") | AC17: =IFERROR(ROUND(AVERAGE(S17:AB17),0),"") | AD17: =IFERROR((AVERAGE(#REF!,#REF!)),"") | AE17: =IF(AG17<20," ",IF(AG17<51,"ED",IF(AG17<67,"DA",IF(AG17<85,"DO","DP")))) | AG17: =IFERROR((SUM(G17,R17,AC17,AD17,AF17)),"") -> 0 | AH17: =IF(AG17="","",(IF(AND(AG17>=1,AG17<=50.499),"REPROBADO",IF(AND(AG17>=50.5,AG17<=100),"APROBADO")))) -> FALSE
